{"level":"ERROR","location":"[__auth_resp:666] data_ws","message":"0","timestamp":"2023-08-19 21:08:18,971+0530","service":"FyersDataSocket","exception":"Traceback (most recent call last):\n  File \"C:\\Users\\Sayan\\AppData\\Local\\Programs\\Python\\Python311\\Lib\\site-packages\\fyers_apiv3\\FyersWebsocket\\data_ws.py\", line 643, in __auth_resp\n    self.On_message(\n  File \"C:\\Users\\Sayan\\AppData\\Local\\Programs\\Python\\Python311\\Lib\\site-packages\\fyers_apiv3\\FyersWebsocket\\data_ws.py\", line 1403, in On_message\n    self.OnMessage(message)\n  File \"c:\\sayan's-project\\fyers\\fy_websocket.py\", line 11, in onmessage\n    live_data[message[0]['symbol']] = message[0]['ltp']\n                                      ~~~~~~~^^^\nKeyError: 0","exception_name":"KeyError"}
{"level":"ERROR","location":"[__lite_full_mode_resp:823] data_ws","message":"0","timestamp":"2023-08-19 21:08:19,538+0530","service":"FyersDataSocket","exception":"Traceback (most recent call last):\n  File \"C:\\Users\\Sayan\\AppData\\Local\\Programs\\Python\\Python311\\Lib\\site-packages\\fyers_apiv3\\FyersWebsocket\\data_ws.py\", line 805, in __lite_full_mode_resp\n    self.On_message(\n  File \"C:\\Users\\Sayan\\AppData\\Local\\Programs\\Python\\Python311\\Lib\\site-packages\\fyers_apiv3\\FyersWebsocket\\data_ws.py\", line 1403, in On_message\n    self.OnMessage(message)\n  File \"c:\\sayan's-project\\fyers\\fy_websocket.py\", line 11, in onmessage\n    live_data[message[0]['symbol']] = message[0]['ltp']\n                                      ~~~~~~~^^^\nKeyError: 0","exception_name":"KeyError"}
{"level":"ERROR","location":"[__subscribe_resp:707] data_ws","message":"0","timestamp":"2023-08-19 21:08:21,258+0530","service":"FyersDataSocket","exception":"Traceback (most recent call last):\n  File \"C:\\Users\\Sayan\\AppData\\Local\\Programs\\Python\\Python311\\Lib\\site-packages\\fyers_apiv3\\FyersWebsocket\\data_ws.py\", line 688, in __subscribe_resp\n    self.On_message(\n  File \"C:\\Users\\Sayan\\AppData\\Local\\Programs\\Python\\Python311\\Lib\\site-packages\\fyers_apiv3\\FyersWebsocket\\data_ws.py\", line 1403, in On_message\n    self.OnMessage(message)\n  File \"c:\\sayan's-project\\fyers\\fy_websocket.py\", line 11, in onmessage\n    live_data[message[0]['symbol']] = message[0]['ltp']\n                                      ~~~~~~~^^^\nKeyError: 0","exception_name":"KeyError"}
{"level":"ERROR","location":"[__response_output:976] data_ws","message":"0","timestamp":"2023-08-19 21:08:21,492+0530","service":"FyersDataSocket","exception":"Traceback (most recent call last):\n  File \"C:\\Users\\Sayan\\AppData\\Local\\Programs\\Python\\Python311\\Lib\\site-packages\\fyers_apiv3\\FyersWebsocket\\data_ws.py\", line 973, in __response_output\n    self.On_message(response)\n  File \"C:\\Users\\Sayan\\AppData\\Local\\Programs\\Python\\Python311\\Lib\\site-packages\\fyers_apiv3\\FyersWebsocket\\data_ws.py\", line 1403, in On_message\n    self.OnMessage(message)\n  File \"c:\\sayan's-project\\fyers\\fy_websocket.py\", line 11, in onmessage\n    live_data[message[0]['symbol']] = message[0]['ltp']\n                                      ~~~~~~~^^^\nKeyError: 0","exception_name":"KeyError"}
{"level":"ERROR","location":"[__response_output:976] data_ws","message":"0","timestamp":"2023-08-19 21:08:21,523+0530","service":"FyersDataSocket","exception":"Traceback (most recent call last):\n  File \"C:\\Users\\Sayan\\AppData\\Local\\Programs\\Python\\Python311\\Lib\\site-packages\\fyers_apiv3\\FyersWebsocket\\data_ws.py\", line 973, in __response_output\n    self.On_message(response)\n  File \"C:\\Users\\Sayan\\AppData\\Local\\Programs\\Python\\Python311\\Lib\\site-packages\\fyers_apiv3\\FyersWebsocket\\data_ws.py\", line 1403, in On_message\n    self.OnMessage(message)\n  File \"c:\\sayan's-project\\fyers\\fy_websocket.py\", line 11, in onmessage\n    live_data[message[0]['symbol']] = message[0]['ltp']\n                                      ~~~~~~~^^^\nKeyError: 0","exception_name":"KeyError"}
{"level":"ERROR","location":"[__auth_resp:666] data_ws","message":"0","timestamp":"2023-08-19 21:10:51,643+0530","service":"FyersDataSocket","exception":"Traceback (most recent call last):\n  File \"C:\\Users\\Sayan\\AppData\\Local\\Programs\\Python\\Python311\\Lib\\site-packages\\fyers_apiv3\\FyersWebsocket\\data_ws.py\", line 643, in __auth_resp\n    self.On_message(\n  File \"C:\\Users\\Sayan\\AppData\\Local\\Programs\\Python\\Python311\\Lib\\site-packages\\fyers_apiv3\\FyersWebsocket\\data_ws.py\", line 1403, in On_message\n    self.OnMessage(message)\n  File \"c:\\sayan's-project\\fyers\\fy_websocket.py\", line 11, in onmessage\n    live_data[message[0]['symbol']] = message[0]['ltp']\n                                      ~~~~~~~^^^\nKeyError: 0","exception_name":"KeyError"}
{"level":"ERROR","location":"[__lite_full_mode_resp:823] data_ws","message":"0","timestamp":"2023-08-19 21:10:52,210+0530","service":"FyersDataSocket","exception":"Traceback (most recent call last):\n  File \"C:\\Users\\Sayan\\AppData\\Local\\Programs\\Python\\Python311\\Lib\\site-packages\\fyers_apiv3\\FyersWebsocket\\data_ws.py\", line 805, in __lite_full_mode_resp\n    self.On_message(\n  File \"C:\\Users\\Sayan\\AppData\\Local\\Programs\\Python\\Python311\\Lib\\site-packages\\fyers_apiv3\\FyersWebsocket\\data_ws.py\", line 1403, in On_message\n    self.OnMessage(message)\n  File \"c:\\sayan's-project\\fyers\\fy_websocket.py\", line 11, in onmessage\n    live_data[message[0]['symbol']] = message[0]['ltp']\n                                      ~~~~~~~^^^\nKeyError: 0","exception_name":"KeyError"}
{"level":"ERROR","location":"[__subscribe_resp:707] data_ws","message":"0","timestamp":"2023-08-19 21:10:53,808+0530","service":"FyersDataSocket","exception":"Traceback (most recent call last):\n  File \"C:\\Users\\Sayan\\AppData\\Local\\Programs\\Python\\Python311\\Lib\\site-packages\\fyers_apiv3\\FyersWebsocket\\data_ws.py\", line 688, in __subscribe_resp\n    self.On_message(\n  File \"C:\\Users\\Sayan\\AppData\\Local\\Programs\\Python\\Python311\\Lib\\site-packages\\fyers_apiv3\\FyersWebsocket\\data_ws.py\", line 1403, in On_message\n    self.OnMessage(message)\n  File \"c:\\sayan's-project\\fyers\\fy_websocket.py\", line 11, in onmessage\n    live_data[message[0]['symbol']] = message[0]['ltp']\n                                      ~~~~~~~^^^\nKeyError: 0","exception_name":"KeyError"}
{"level":"ERROR","location":"[__response_output:976] data_ws","message":"0","timestamp":"2023-08-19 21:10:54,282+0530","service":"FyersDataSocket","exception":"Traceback (most recent call last):\n  File \"C:\\Users\\Sayan\\AppData\\Local\\Programs\\Python\\Python311\\Lib\\site-packages\\fyers_apiv3\\FyersWebsocket\\data_ws.py\", line 973, in __response_output\n    self.On_message(response)\n  File \"C:\\Users\\Sayan\\AppData\\Local\\Programs\\Python\\Python311\\Lib\\site-packages\\fyers_apiv3\\FyersWebsocket\\data_ws.py\", line 1403, in On_message\n    self.OnMessage(message)\n  File \"c:\\sayan's-project\\fyers\\fy_websocket.py\", line 11, in onmessage\n    live_data[message[0]['symbol']] = message[0]['ltp']\n                                      ~~~~~~~^^^\nKeyError: 0","exception_name":"KeyError"}
{"level":"ERROR","location":"[__response_output:976] data_ws","message":"0","timestamp":"2023-08-19 21:10:54,376+0530","service":"FyersDataSocket","exception":"Traceback (most recent call last):\n  File \"C:\\Users\\Sayan\\AppData\\Local\\Programs\\Python\\Python311\\Lib\\site-packages\\fyers_apiv3\\FyersWebsocket\\data_ws.py\", line 973, in __response_output\n    self.On_message(response)\n  File \"C:\\Users\\Sayan\\AppData\\Local\\Programs\\Python\\Python311\\Lib\\site-packages\\fyers_apiv3\\FyersWebsocket\\data_ws.py\", line 1403, in On_message\n    self.OnMessage(message)\n  File \"c:\\sayan's-project\\fyers\\fy_websocket.py\", line 11, in onmessage\n    live_data[message[0]['symbol']] = message[0]['ltp']\n                                      ~~~~~~~^^^\nKeyError: 0","exception_name":"KeyError"}
{"level":"ERROR","location":"[__auth_resp:666] data_ws","message":"0","timestamp":"2023-08-19 21:11:03,887+0530","service":"FyersDataSocket","exception":"Traceback (most recent call last):\n  File \"C:\\Users\\Sayan\\AppData\\Local\\Programs\\Python\\Python311\\Lib\\site-packages\\fyers_apiv3\\FyersWebsocket\\data_ws.py\", line 643, in __auth_resp\n    self.On_message(\n  File \"C:\\Users\\Sayan\\AppData\\Local\\Programs\\Python\\Python311\\Lib\\site-packages\\fyers_apiv3\\FyersWebsocket\\data_ws.py\", line 1403, in On_message\n    self.OnMessage(message)\n  File \"c:\\sayan's-project\\fyers\\fy_websocket.py\", line 11, in onmessage\n    live_data[message[0]['symbol']] = message[0]['ltp']\n                                      ~~~~~~~^^^\nKeyError: 0","exception_name":"KeyError"}
{"level":"ERROR","location":"[__lite_full_mode_resp:823] data_ws","message":"0","timestamp":"2023-08-19 21:11:04,456+0530","service":"FyersDataSocket","exception":"Traceback (most recent call last):\n  File \"C:\\Users\\Sayan\\AppData\\Local\\Programs\\Python\\Python311\\Lib\\site-packages\\fyers_apiv3\\FyersWebsocket\\data_ws.py\", line 805, in __lite_full_mode_resp\n    self.On_message(\n  File \"C:\\Users\\Sayan\\AppData\\Local\\Programs\\Python\\Python311\\Lib\\site-packages\\fyers_apiv3\\FyersWebsocket\\data_ws.py\", line 1403, in On_message\n    self.OnMessage(message)\n  File \"c:\\sayan's-project\\fyers\\fy_websocket.py\", line 11, in onmessage\n    live_data[message[0]['symbol']] = message[0]['ltp']\n                                      ~~~~~~~^^^\nKeyError: 0","exception_name":"KeyError"}
{"level":"ERROR","location":"[__subscribe_resp:707] data_ws","message":"0","timestamp":"2023-08-19 21:11:06,192+0530","service":"FyersDataSocket","exception":"Traceback (most recent call last):\n  File \"C:\\Users\\Sayan\\AppData\\Local\\Programs\\Python\\Python311\\Lib\\site-packages\\fyers_apiv3\\FyersWebsocket\\data_ws.py\", line 688, in __subscribe_resp\n    self.On_message(\n  File \"C:\\Users\\Sayan\\AppData\\Local\\Programs\\Python\\Python311\\Lib\\site-packages\\fyers_apiv3\\FyersWebsocket\\data_ws.py\", line 1403, in On_message\n    self.OnMessage(message)\n  File \"c:\\sayan's-project\\fyers\\fy_websocket.py\", line 11, in onmessage\n    live_data[message[0]['symbol']] = message[0]['ltp']\n                                      ~~~~~~~^^^\nKeyError: 0","exception_name":"KeyError"}
{"level":"ERROR","location":"[__response_output:976] data_ws","message":"0","timestamp":"2023-08-19 21:11:06,423+0530","service":"FyersDataSocket","exception":"Traceback (most recent call last):\n  File \"C:\\Users\\Sayan\\AppData\\Local\\Programs\\Python\\Python311\\Lib\\site-packages\\fyers_apiv3\\FyersWebsocket\\data_ws.py\", line 973, in __response_output\n    self.On_message(response)\n  File \"C:\\Users\\Sayan\\AppData\\Local\\Programs\\Python\\Python311\\Lib\\site-packages\\fyers_apiv3\\FyersWebsocket\\data_ws.py\", line 1403, in On_message\n    self.OnMessage(message)\n  File \"c:\\sayan's-project\\fyers\\fy_websocket.py\", line 11, in onmessage\n    live_data[message[0]['symbol']] = message[0]['ltp']\n                                      ~~~~~~~^^^\nKeyError: 0","exception_name":"KeyError"}
{"level":"ERROR","location":"[__response_output:976] data_ws","message":"0","timestamp":"2023-08-19 21:11:06,454+0530","service":"FyersDataSocket","exception":"Traceback (most recent call last):\n  File \"C:\\Users\\Sayan\\AppData\\Local\\Programs\\Python\\Python311\\Lib\\site-packages\\fyers_apiv3\\FyersWebsocket\\data_ws.py\", line 973, in __response_output\n    self.On_message(response)\n  File \"C:\\Users\\Sayan\\AppData\\Local\\Programs\\Python\\Python311\\Lib\\site-packages\\fyers_apiv3\\FyersWebsocket\\data_ws.py\", line 1403, in On_message\n    self.OnMessage(message)\n  File \"c:\\sayan's-project\\fyers\\fy_websocket.py\", line 11, in onmessage\n    live_data[message[0]['symbol']] = message[0]['ltp']\n                                      ~~~~~~~^^^\nKeyError: 0","exception_name":"KeyError"}
{"level":"ERROR","location":"[__auth_resp:666] data_ws","message":"0","timestamp":"2023-08-19 21:12:04,353+0530","service":"FyersDataSocket","exception":"Traceback (most recent call last):\n  File \"C:\\Users\\Sayan\\AppData\\Local\\Programs\\Python\\Python311\\Lib\\site-packages\\fyers_apiv3\\FyersWebsocket\\data_ws.py\", line 643, in __auth_resp\n    self.On_message(\n  File \"C:\\Users\\Sayan\\AppData\\Local\\Programs\\Python\\Python311\\Lib\\site-packages\\fyers_apiv3\\FyersWebsocket\\data_ws.py\", line 1403, in On_message\n    self.OnMessage(message)\n  File \"c:\\sayan's-project\\fyers\\fy_websocket.py\", line 11, in onmessage\n    live_data[message[0]['symbol']] = message[0]['ltp']\n                                      ~~~~~~~^^^\nKeyError: 0","exception_name":"KeyError"}
{"level":"ERROR","location":"[__lite_full_mode_resp:823] data_ws","message":"0","timestamp":"2023-08-19 21:12:04,923+0530","service":"FyersDataSocket","exception":"Traceback (most recent call last):\n  File \"C:\\Users\\Sayan\\AppData\\Local\\Programs\\Python\\Python311\\Lib\\site-packages\\fyers_apiv3\\FyersWebsocket\\data_ws.py\", line 805, in __lite_full_mode_resp\n    self.On_message(\n  File \"C:\\Users\\Sayan\\AppData\\Local\\Programs\\Python\\Python311\\Lib\\site-packages\\fyers_apiv3\\FyersWebsocket\\data_ws.py\", line 1403, in On_message\n    self.OnMessage(message)\n  File \"c:\\sayan's-project\\fyers\\fy_websocket.py\", line 11, in onmessage\n    live_data[message[0]['symbol']] = message[0]['ltp']\n                                      ~~~~~~~^^^\nKeyError: 0","exception_name":"KeyError"}
{"level":"ERROR","location":"[__subscribe_resp:707] data_ws","message":"0","timestamp":"2023-08-19 21:12:06,789+0530","service":"FyersDataSocket","exception":"Traceback (most recent call last):\n  File \"C:\\Users\\Sayan\\AppData\\Local\\Programs\\Python\\Python311\\Lib\\site-packages\\fyers_apiv3\\FyersWebsocket\\data_ws.py\", line 688, in __subscribe_resp\n    self.On_message(\n  File \"C:\\Users\\Sayan\\AppData\\Local\\Programs\\Python\\Python311\\Lib\\site-packages\\fyers_apiv3\\FyersWebsocket\\data_ws.py\", line 1403, in On_message\n    self.OnMessage(message)\n  File \"c:\\sayan's-project\\fyers\\fy_websocket.py\", line 11, in onmessage\n    live_data[message[0]['symbol']] = message[0]['ltp']\n                                      ~~~~~~~^^^\nKeyError: 0","exception_name":"KeyError"}
{"level":"ERROR","location":"[__response_output:976] data_ws","message":"0","timestamp":"2023-08-19 21:12:06,867+0530","service":"FyersDataSocket","exception":"Traceback (most recent call last):\n  File \"C:\\Users\\Sayan\\AppData\\Local\\Programs\\Python\\Python311\\Lib\\site-packages\\fyers_apiv3\\FyersWebsocket\\data_ws.py\", line 973, in __response_output\n    self.On_message(response)\n  File \"C:\\Users\\Sayan\\AppData\\Local\\Programs\\Python\\Python311\\Lib\\site-packages\\fyers_apiv3\\FyersWebsocket\\data_ws.py\", line 1403, in On_message\n    self.OnMessage(message)\n  File \"c:\\sayan's-project\\fyers\\fy_websocket.py\", line 11, in onmessage\n    live_data[message[0]['symbol']] = message[0]['ltp']\n                                      ~~~~~~~^^^\nKeyError: 0","exception_name":"KeyError"}
{"level":"ERROR","location":"[__response_output:976] data_ws","message":"0","timestamp":"2023-08-19 21:12:06,914+0530","service":"FyersDataSocket","exception":"Traceback (most recent call last):\n  File \"C:\\Users\\Sayan\\AppData\\Local\\Programs\\Python\\Python311\\Lib\\site-packages\\fyers_apiv3\\FyersWebsocket\\data_ws.py\", line 973, in __response_output\n    self.On_message(response)\n  File \"C:\\Users\\Sayan\\AppData\\Local\\Programs\\Python\\Python311\\Lib\\site-packages\\fyers_apiv3\\FyersWebsocket\\data_ws.py\", line 1403, in On_message\n    self.OnMessage(message)\n  File \"c:\\sayan's-project\\fyers\\fy_websocket.py\", line 11, in onmessage\n    live_data[message[0]['symbol']] = message[0]['ltp']\n                                      ~~~~~~~^^^\nKeyError: 0","exception_name":"KeyError"}
{"level":"ERROR","location":"[__auth_resp:666] data_ws","message":"0","timestamp":"2023-08-19 21:12:20,890+0530","service":"FyersDataSocket","exception":"Traceback (most recent call last):\n  File \"C:\\Users\\Sayan\\AppData\\Local\\Programs\\Python\\Python311\\Lib\\site-packages\\fyers_apiv3\\FyersWebsocket\\data_ws.py\", line 643, in __auth_resp\n    self.On_message(\n  File \"C:\\Users\\Sayan\\AppData\\Local\\Programs\\Python\\Python311\\Lib\\site-packages\\fyers_apiv3\\FyersWebsocket\\data_ws.py\", line 1403, in On_message\n    self.OnMessage(message)\n  File \"c:\\sayan's-project\\fyers\\fy_websocket.py\", line 11, in onmessage\n    live_data[message[0]['symbol']] = message[0]['ltp']\n                                      ~~~~~~~^^^\nKeyError: 0","exception_name":"KeyError"}
{"level":"ERROR","location":"[__lite_full_mode_resp:823] data_ws","message":"0","timestamp":"2023-08-19 21:12:21,429+0530","service":"FyersDataSocket","exception":"Traceback (most recent call last):\n  File \"C:\\Users\\Sayan\\AppData\\Local\\Programs\\Python\\Python311\\Lib\\site-packages\\fyers_apiv3\\FyersWebsocket\\data_ws.py\", line 805, in __lite_full_mode_resp\n    self.On_message(\n  File \"C:\\Users\\Sayan\\AppData\\Local\\Programs\\Python\\Python311\\Lib\\site-packages\\fyers_apiv3\\FyersWebsocket\\data_ws.py\", line 1403, in On_message\n    self.OnMessage(message)\n  File \"c:\\sayan's-project\\fyers\\fy_websocket.py\", line 11, in onmessage\n    live_data[message[0]['symbol']] = message[0]['ltp']\n                                      ~~~~~~~^^^\nKeyError: 0","exception_name":"KeyError"}
{"level":"ERROR","location":"[__subscribe_resp:707] data_ws","message":"0","timestamp":"2023-08-19 21:12:23,027+0530","service":"FyersDataSocket","exception":"Traceback (most recent call last):\n  File \"C:\\Users\\Sayan\\AppData\\Local\\Programs\\Python\\Python311\\Lib\\site-packages\\fyers_apiv3\\FyersWebsocket\\data_ws.py\", line 688, in __subscribe_resp\n    self.On_message(\n  File \"C:\\Users\\Sayan\\AppData\\Local\\Programs\\Python\\Python311\\Lib\\site-packages\\fyers_apiv3\\FyersWebsocket\\data_ws.py\", line 1403, in On_message\n    self.OnMessage(message)\n  File \"c:\\sayan's-project\\fyers\\fy_websocket.py\", line 11, in onmessage\n    live_data[message[0]['symbol']] = message[0]['ltp']\n                                      ~~~~~~~^^^\nKeyError: 0","exception_name":"KeyError"}
{"level":"ERROR","location":"[__response_output:976] data_ws","message":"0","timestamp":"2023-08-19 21:12:23,389+0530","service":"FyersDataSocket","exception":"Traceback (most recent call last):\n  File \"C:\\Users\\Sayan\\AppData\\Local\\Programs\\Python\\Python311\\Lib\\site-packages\\fyers_apiv3\\FyersWebsocket\\data_ws.py\", line 973, in __response_output\n    self.On_message(response)\n  File \"C:\\Users\\Sayan\\AppData\\Local\\Programs\\Python\\Python311\\Lib\\site-packages\\fyers_apiv3\\FyersWebsocket\\data_ws.py\", line 1403, in On_message\n    self.OnMessage(message)\n  File \"c:\\sayan's-project\\fyers\\fy_websocket.py\", line 11, in onmessage\n    live_data[message[0]['symbol']] = message[0]['ltp']\n                                      ~~~~~~~^^^\nKeyError: 0","exception_name":"KeyError"}
{"level":"ERROR","location":"[__response_output:976] data_ws","message":"0","timestamp":"2023-08-19 21:12:23,421+0530","service":"FyersDataSocket","exception":"Traceback (most recent call last):\n  File \"C:\\Users\\Sayan\\AppData\\Local\\Programs\\Python\\Python311\\Lib\\site-packages\\fyers_apiv3\\FyersWebsocket\\data_ws.py\", line 973, in __response_output\n    self.On_message(response)\n  File \"C:\\Users\\Sayan\\AppData\\Local\\Programs\\Python\\Python311\\Lib\\site-packages\\fyers_apiv3\\FyersWebsocket\\data_ws.py\", line 1403, in On_message\n    self.OnMessage(message)\n  File \"c:\\sayan's-project\\fyers\\fy_websocket.py\", line 11, in onmessage\n    live_data[message[0]['symbol']] = message[0]['ltp']\n                                      ~~~~~~~^^^\nKeyError: 0","exception_name":"KeyError"}
{"level":"ERROR","location":"[__auth_resp:666] data_ws","message":"0","timestamp":"2023-08-19 21:12:31,865+0530","service":"FyersDataSocket","exception":"Traceback (most recent call last):\n  File \"C:\\Users\\Sayan\\AppData\\Local\\Programs\\Python\\Python311\\Lib\\site-packages\\fyers_apiv3\\FyersWebsocket\\data_ws.py\", line 643, in __auth_resp\n    self.On_message(\n  File \"C:\\Users\\Sayan\\AppData\\Local\\Programs\\Python\\Python311\\Lib\\site-packages\\fyers_apiv3\\FyersWebsocket\\data_ws.py\", line 1403, in On_message\n    self.OnMessage(message)\n  File \"c:\\sayan's-project\\fyers\\fy_websocket.py\", line 11, in onmessage\n    live_data[message[0]['symbol']] = message[0]['ltp']\n                                      ~~~~~~~^^^\nKeyError: 0","exception_name":"KeyError"}
{"level":"ERROR","location":"[__lite_full_mode_resp:823] data_ws","message":"0","timestamp":"2023-08-19 21:12:32,436+0530","service":"FyersDataSocket","exception":"Traceback (most recent call last):\n  File \"C:\\Users\\Sayan\\AppData\\Local\\Programs\\Python\\Python311\\Lib\\site-packages\\fyers_apiv3\\FyersWebsocket\\data_ws.py\", line 805, in __lite_full_mode_resp\n    self.On_message(\n  File \"C:\\Users\\Sayan\\AppData\\Local\\Programs\\Python\\Python311\\Lib\\site-packages\\fyers_apiv3\\FyersWebsocket\\data_ws.py\", line 1403, in On_message\n    self.OnMessage(message)\n  File \"c:\\sayan's-project\\fyers\\fy_websocket.py\", line 11, in onmessage\n    live_data[message[0]['symbol']] = message[0]['ltp']\n                                      ~~~~~~~^^^\nKeyError: 0","exception_name":"KeyError"}
{"level":"ERROR","location":"[__subscribe_resp:707] data_ws","message":"0","timestamp":"2023-08-19 21:12:34,080+0530","service":"FyersDataSocket","exception":"Traceback (most recent call last):\n  File \"C:\\Users\\Sayan\\AppData\\Local\\Programs\\Python\\Python311\\Lib\\site-packages\\fyers_apiv3\\FyersWebsocket\\data_ws.py\", line 688, in __subscribe_resp\n    self.On_message(\n  File \"C:\\Users\\Sayan\\AppData\\Local\\Programs\\Python\\Python311\\Lib\\site-packages\\fyers_apiv3\\FyersWebsocket\\data_ws.py\", line 1403, in On_message\n    self.OnMessage(message)\n  File \"c:\\sayan's-project\\fyers\\fy_websocket.py\", line 11, in onmessage\n    live_data[message[0]['symbol']] = message[0]['ltp']\n                                      ~~~~~~~^^^\nKeyError: 0","exception_name":"KeyError"}
{"level":"ERROR","location":"[__response_output:976] data_ws","message":"0","timestamp":"2023-08-19 21:12:34,381+0530","service":"FyersDataSocket","exception":"Traceback (most recent call last):\n  File \"C:\\Users\\Sayan\\AppData\\Local\\Programs\\Python\\Python311\\Lib\\site-packages\\fyers_apiv3\\FyersWebsocket\\data_ws.py\", line 973, in __response_output\n    self.On_message(response)\n  File \"C:\\Users\\Sayan\\AppData\\Local\\Programs\\Python\\Python311\\Lib\\site-packages\\fyers_apiv3\\FyersWebsocket\\data_ws.py\", line 1403, in On_message\n    self.OnMessage(message)\n  File \"c:\\sayan's-project\\fyers\\fy_websocket.py\", line 11, in onmessage\n    live_data[message[0]['symbol']] = message[0]['ltp']\n                                      ~~~~~~~^^^\nKeyError: 0","exception_name":"KeyError"}
{"level":"ERROR","location":"[__response_output:976] data_ws","message":"0","timestamp":"2023-08-19 21:12:34,397+0530","service":"FyersDataSocket","exception":"Traceback (most recent call last):\n  File \"C:\\Users\\Sayan\\AppData\\Local\\Programs\\Python\\Python311\\Lib\\site-packages\\fyers_apiv3\\FyersWebsocket\\data_ws.py\", line 973, in __response_output\n    self.On_message(response)\n  File \"C:\\Users\\Sayan\\AppData\\Local\\Programs\\Python\\Python311\\Lib\\site-packages\\fyers_apiv3\\FyersWebsocket\\data_ws.py\", line 1403, in On_message\n    self.OnMessage(message)\n  File \"c:\\sayan's-project\\fyers\\fy_websocket.py\", line 11, in onmessage\n    live_data[message[0]['symbol']] = message[0]['ltp']\n                                      ~~~~~~~^^^\nKeyError: 0","exception_name":"KeyError"}
{"level":"ERROR","location":"[__auth_resp:666] data_ws","message":"0","timestamp":"2023-08-19 21:14:42,251+0530","service":"FyersDataSocket","exception":"Traceback (most recent call last):\n  File \"C:\\Users\\Sayan\\AppData\\Local\\Programs\\Python\\Python311\\Lib\\site-packages\\fyers_apiv3\\FyersWebsocket\\data_ws.py\", line 643, in __auth_resp\n    self.On_message(\n  File \"C:\\Users\\Sayan\\AppData\\Local\\Programs\\Python\\Python311\\Lib\\site-packages\\fyers_apiv3\\FyersWebsocket\\data_ws.py\", line 1403, in On_message\n    self.OnMessage(message)\n  File \"c:\\sayan's-project\\fyers\\fy_websocket.py\", line 11, in onmessage\n    live_data[message[0]['symbol']] = message[0]['ltp']\n                                      ~~~~~~~^^^\nKeyError: 0","exception_name":"KeyError"}
{"level":"ERROR","location":"[__lite_full_mode_resp:823] data_ws","message":"0","timestamp":"2023-08-19 21:14:42,814+0530","service":"FyersDataSocket","exception":"Traceback (most recent call last):\n  File \"C:\\Users\\Sayan\\AppData\\Local\\Programs\\Python\\Python311\\Lib\\site-packages\\fyers_apiv3\\FyersWebsocket\\data_ws.py\", line 805, in __lite_full_mode_resp\n    self.On_message(\n  File \"C:\\Users\\Sayan\\AppData\\Local\\Programs\\Python\\Python311\\Lib\\site-packages\\fyers_apiv3\\FyersWebsocket\\data_ws.py\", line 1403, in On_message\n    self.OnMessage(message)\n  File \"c:\\sayan's-project\\fyers\\fy_websocket.py\", line 11, in onmessage\n    live_data[message[0]['symbol']] = message[0]['ltp']\n                                      ~~~~~~~^^^\nKeyError: 0","exception_name":"KeyError"}
{"level":"ERROR","location":"[__subscribe_resp:707] data_ws","message":"0","timestamp":"2023-08-19 21:14:44,603+0530","service":"FyersDataSocket","exception":"Traceback (most recent call last):\n  File \"C:\\Users\\Sayan\\AppData\\Local\\Programs\\Python\\Python311\\Lib\\site-packages\\fyers_apiv3\\FyersWebsocket\\data_ws.py\", line 688, in __subscribe_resp\n    self.On_message(\n  File \"C:\\Users\\Sayan\\AppData\\Local\\Programs\\Python\\Python311\\Lib\\site-packages\\fyers_apiv3\\FyersWebsocket\\data_ws.py\", line 1403, in On_message\n    self.OnMessage(message)\n  File \"c:\\sayan's-project\\fyers\\fy_websocket.py\", line 11, in onmessage\n    live_data[message[0]['symbol']] = message[0]['ltp']\n                                      ~~~~~~~^^^\nKeyError: 0","exception_name":"KeyError"}
{"level":"ERROR","location":"[__response_output:976] data_ws","message":"0","timestamp":"2023-08-19 21:14:44,809+0530","service":"FyersDataSocket","exception":"Traceback (most recent call last):\n  File \"C:\\Users\\Sayan\\AppData\\Local\\Programs\\Python\\Python311\\Lib\\site-packages\\fyers_apiv3\\FyersWebsocket\\data_ws.py\", line 973, in __response_output\n    self.On_message(response)\n  File \"C:\\Users\\Sayan\\AppData\\Local\\Programs\\Python\\Python311\\Lib\\site-packages\\fyers_apiv3\\FyersWebsocket\\data_ws.py\", line 1403, in On_message\n    self.OnMessage(message)\n  File \"c:\\sayan's-project\\fyers\\fy_websocket.py\", line 11, in onmessage\n    live_data[message[0]['symbol']] = message[0]['ltp']\n                                      ~~~~~~~^^^\nKeyError: 0","exception_name":"KeyError"}
{"level":"ERROR","location":"[__response_output:976] data_ws","message":"0","timestamp":"2023-08-19 21:14:44,825+0530","service":"FyersDataSocket","exception":"Traceback (most recent call last):\n  File \"C:\\Users\\Sayan\\AppData\\Local\\Programs\\Python\\Python311\\Lib\\site-packages\\fyers_apiv3\\FyersWebsocket\\data_ws.py\", line 973, in __response_output\n    self.On_message(response)\n  File \"C:\\Users\\Sayan\\AppData\\Local\\Programs\\Python\\Python311\\Lib\\site-packages\\fyers_apiv3\\FyersWebsocket\\data_ws.py\", line 1403, in On_message\n    self.OnMessage(message)\n  File \"c:\\sayan's-project\\fyers\\fy_websocket.py\", line 11, in onmessage\n    live_data[message[0]['symbol']] = message[0]['ltp']\n                                      ~~~~~~~^^^\nKeyError: 0","exception_name":"KeyError"}
{"level":"ERROR","location":"[__auth_resp:666] data_ws","message":"0","timestamp":"2023-08-19 21:15:35,518+0530","service":"FyersDataSocket","exception":"Traceback (most recent call last):\n  File \"C:\\Users\\Sayan\\AppData\\Local\\Programs\\Python\\Python311\\Lib\\site-packages\\fyers_apiv3\\FyersWebsocket\\data_ws.py\", line 643, in __auth_resp\n    self.On_message(\n  File \"C:\\Users\\Sayan\\AppData\\Local\\Programs\\Python\\Python311\\Lib\\site-packages\\fyers_apiv3\\FyersWebsocket\\data_ws.py\", line 1403, in On_message\n    self.OnMessage(message)\n  File \"c:\\sayan's-project\\fyers\\fy_websocket.py\", line 11, in onmessage\n    live_data[message[0]['symbol']] = message[0]['ltp']\n                                      ~~~~~~~^^^\nKeyError: 0","exception_name":"KeyError"}
{"level":"ERROR","location":"[__lite_full_mode_resp:823] data_ws","message":"0","timestamp":"2023-08-19 21:15:36,087+0530","service":"FyersDataSocket","exception":"Traceback (most recent call last):\n  File \"C:\\Users\\Sayan\\AppData\\Local\\Programs\\Python\\Python311\\Lib\\site-packages\\fyers_apiv3\\FyersWebsocket\\data_ws.py\", line 805, in __lite_full_mode_resp\n    self.On_message(\n  File \"C:\\Users\\Sayan\\AppData\\Local\\Programs\\Python\\Python311\\Lib\\site-packages\\fyers_apiv3\\FyersWebsocket\\data_ws.py\", line 1403, in On_message\n    self.OnMessage(message)\n  File \"c:\\sayan's-project\\fyers\\fy_websocket.py\", line 11, in onmessage\n    live_data[message[0]['symbol']] = message[0]['ltp']\n                                      ~~~~~~~^^^\nKeyError: 0","exception_name":"KeyError"}
{"level":"ERROR","location":"[__subscribe_resp:707] data_ws","message":"0","timestamp":"2023-08-19 21:15:38,809+0530","service":"FyersDataSocket","exception":"Traceback (most recent call last):\n  File \"C:\\Users\\Sayan\\AppData\\Local\\Programs\\Python\\Python311\\Lib\\site-packages\\fyers_apiv3\\FyersWebsocket\\data_ws.py\", line 688, in __subscribe_resp\n    self.On_message(\n  File \"C:\\Users\\Sayan\\AppData\\Local\\Programs\\Python\\Python311\\Lib\\site-packages\\fyers_apiv3\\FyersWebsocket\\data_ws.py\", line 1403, in On_message\n    self.OnMessage(message)\n  File \"c:\\sayan's-project\\fyers\\fy_websocket.py\", line 11, in onmessage\n    live_data[message[0]['symbol']] = message[0]['ltp']\n                                      ~~~~~~~^^^\nKeyError: 0","exception_name":"KeyError"}
{"level":"ERROR","location":"[__response_output:976] data_ws","message":"0","timestamp":"2023-08-19 21:15:39,041+0530","service":"FyersDataSocket","exception":"Traceback (most recent call last):\n  File \"C:\\Users\\Sayan\\AppData\\Local\\Programs\\Python\\Python311\\Lib\\site-packages\\fyers_apiv3\\FyersWebsocket\\data_ws.py\", line 973, in __response_output\n    self.On_message(response)\n  File \"C:\\Users\\Sayan\\AppData\\Local\\Programs\\Python\\Python311\\Lib\\site-packages\\fyers_apiv3\\FyersWebsocket\\data_ws.py\", line 1403, in On_message\n    self.OnMessage(message)\n  File \"c:\\sayan's-project\\fyers\\fy_websocket.py\", line 11, in onmessage\n    # live_data[message[0]['symbol']] = message[0]['ltp']\n                                      ^^^^^^^^^^\nKeyError: 0","exception_name":"KeyError"}
{"level":"ERROR","location":"[__response_output:976] data_ws","message":"0","timestamp":"2023-08-19 21:15:39,215+0530","service":"FyersDataSocket","exception":"Traceback (most recent call last):\n  File \"C:\\Users\\Sayan\\AppData\\Local\\Programs\\Python\\Python311\\Lib\\site-packages\\fyers_apiv3\\FyersWebsocket\\data_ws.py\", line 973, in __response_output\n    self.On_message(response)\n  File \"C:\\Users\\Sayan\\AppData\\Local\\Programs\\Python\\Python311\\Lib\\site-packages\\fyers_apiv3\\FyersWebsocket\\data_ws.py\", line 1403, in On_message\n    self.OnMessage(message)\n  File \"c:\\sayan's-project\\fyers\\fy_websocket.py\", line 11, in onmessage\n    # live_data[message[0]['symbol']] = message[0]['ltp']\n                                      ^^^^^^^^^^\nKeyError: 0","exception_name":"KeyError"}
{"level":"ERROR","location":"[__auth_resp:666] data_ws","message":"'symbol'","timestamp":"2023-08-19 21:15:41,622+0530","service":"FyersDataSocket","exception":"Traceback (most recent call last):\n  File \"C:\\Users\\Sayan\\AppData\\Local\\Programs\\Python\\Python311\\Lib\\site-packages\\fyers_apiv3\\FyersWebsocket\\data_ws.py\", line 643, in __auth_resp\n    self.On_message(\n  File \"C:\\Users\\Sayan\\AppData\\Local\\Programs\\Python\\Python311\\Lib\\site-packages\\fyers_apiv3\\FyersWebsocket\\data_ws.py\", line 1403, in On_message\n    self.OnMessage(message)\n  File \"c:\\sayan's-project\\fyers\\fy_websocket.py\", line 13, in onmessage\n    print(message['symbol'])\n          ~~~~~~~^^^^^^^^^^\nKeyError: 'symbol'","exception_name":"KeyError"}
{"level":"ERROR","location":"[__lite_full_mode_resp:823] data_ws","message":"'symbol'","timestamp":"2023-08-19 21:15:42,190+0530","service":"FyersDataSocket","exception":"Traceback (most recent call last):\n  File \"C:\\Users\\Sayan\\AppData\\Local\\Programs\\Python\\Python311\\Lib\\site-packages\\fyers_apiv3\\FyersWebsocket\\data_ws.py\", line 805, in __lite_full_mode_resp\n    self.On_message(\n  File \"C:\\Users\\Sayan\\AppData\\Local\\Programs\\Python\\Python311\\Lib\\site-packages\\fyers_apiv3\\FyersWebsocket\\data_ws.py\", line 1403, in On_message\n    self.OnMessage(message)\n  File \"c:\\sayan's-project\\fyers\\fy_websocket.py\", line 13, in onmessage\n    print(message['symbol'])\n          ~~~~~~~^^^^^^^^^^\nKeyError: 'symbol'","exception_name":"KeyError"}
{"level":"ERROR","location":"[__subscribe_resp:707] data_ws","message":"'symbol'","timestamp":"2023-08-19 21:15:43,821+0530","service":"FyersDataSocket","exception":"Traceback (most recent call last):\n  File \"C:\\Users\\Sayan\\AppData\\Local\\Programs\\Python\\Python311\\Lib\\site-packages\\fyers_apiv3\\FyersWebsocket\\data_ws.py\", line 688, in __subscribe_resp\n    self.On_message(\n  File \"C:\\Users\\Sayan\\AppData\\Local\\Programs\\Python\\Python311\\Lib\\site-packages\\fyers_apiv3\\FyersWebsocket\\data_ws.py\", line 1403, in On_message\n    self.OnMessage(message)\n  File \"c:\\sayan's-project\\fyers\\fy_websocket.py\", line 13, in onmessage\n    print(message['symbol'])\n          ~~~~~~~^^^^^^^^^^\nKeyError: 'symbol'","exception_name":"KeyError"}
{"level":"ERROR","location":"[__auth_resp:666] data_ws","message":"'symbol'","timestamp":"2023-08-19 21:16:45,029+0530","service":"FyersDataSocket","exception":"Traceback (most recent call last):\n  File \"C:\\Users\\Sayan\\AppData\\Local\\Programs\\Python\\Python311\\Lib\\site-packages\\fyers_apiv3\\FyersWebsocket\\data_ws.py\", line 643, in __auth_resp\n    self.On_message(\n  File \"C:\\Users\\Sayan\\AppData\\Local\\Programs\\Python\\Python311\\Lib\\site-packages\\fyers_apiv3\\FyersWebsocket\\data_ws.py\", line 1403, in On_message\n    self.OnMessage(message)\n  File \"c:\\sayan's-project\\fyers\\fy_websocket.py\", line 11, in onmessage\n    print(message['symbol']+'= '+message['ltp'])\n          ~~~~~~~^^^^^^^^^^\nKeyError: 'symbol'","exception_name":"KeyError"}
{"level":"ERROR","location":"[__lite_full_mode_resp:823] data_ws","message":"'symbol'","timestamp":"2023-08-19 21:16:45,568+0530","service":"FyersDataSocket","exception":"Traceback (most recent call last):\n  File \"C:\\Users\\Sayan\\AppData\\Local\\Programs\\Python\\Python311\\Lib\\site-packages\\fyers_apiv3\\FyersWebsocket\\data_ws.py\", line 805, in __lite_full_mode_resp\n    self.On_message(\n  File \"C:\\Users\\Sayan\\AppData\\Local\\Programs\\Python\\Python311\\Lib\\site-packages\\fyers_apiv3\\FyersWebsocket\\data_ws.py\", line 1403, in On_message\n    self.OnMessage(message)\n  File \"c:\\sayan's-project\\fyers\\fy_websocket.py\", line 11, in onmessage\n    print(message['symbol']+'= '+message['ltp'])\n          ~~~~~~~^^^^^^^^^^\nKeyError: 'symbol'","exception_name":"KeyError"}
{"level":"ERROR","location":"[__subscribe_resp:707] data_ws","message":"'symbol'","timestamp":"2023-08-19 21:16:47,715+0530","service":"FyersDataSocket","exception":"Traceback (most recent call last):\n  File \"C:\\Users\\Sayan\\AppData\\Local\\Programs\\Python\\Python311\\Lib\\site-packages\\fyers_apiv3\\FyersWebsocket\\data_ws.py\", line 688, in __subscribe_resp\n    self.On_message(\n  File \"C:\\Users\\Sayan\\AppData\\Local\\Programs\\Python\\Python311\\Lib\\site-packages\\fyers_apiv3\\FyersWebsocket\\data_ws.py\", line 1403, in On_message\n    self.OnMessage(message)\n  File \"c:\\sayan's-project\\fyers\\fy_websocket.py\", line 11, in onmessage\n    print(message['symbol']+'= '+message['ltp'])\n          ~~~~~~~^^^^^^^^^^\nKeyError: 'symbol'","exception_name":"KeyError"}
{"level":"ERROR","location":"[__response_output:976] data_ws","message":"can only concatenate str (not \"float\") to str","timestamp":"2023-08-19 21:16:48,092+0530","service":"FyersDataSocket","exception":"Traceback (most recent call last):\n  File \"C:\\Users\\Sayan\\AppData\\Local\\Programs\\Python\\Python311\\Lib\\site-packages\\fyers_apiv3\\FyersWebsocket\\data_ws.py\", line 973, in __response_output\n    self.On_message(response)\n  File \"C:\\Users\\Sayan\\AppData\\Local\\Programs\\Python\\Python311\\Lib\\site-packages\\fyers_apiv3\\FyersWebsocket\\data_ws.py\", line 1403, in On_message\n    self.OnMessage(message)\n  File \"c:\\sayan's-project\\fyers\\fy_websocket.py\", line 11, in onmessage\n    print(message['symbol']+'= '+message['ltp'])\n          ~~~~~~~~~~~~~~~~~~~~~~^~~~~~~~~~~~~~~\nTypeError: can only concatenate str (not \"float\") to str","exception_name":"TypeError"}
{"level":"ERROR","location":"[__response_output:976] data_ws","message":"can only concatenate str (not \"float\") to str","timestamp":"2023-08-19 21:16:48,123+0530","service":"FyersDataSocket","exception":"Traceback (most recent call last):\n  File \"C:\\Users\\Sayan\\AppData\\Local\\Programs\\Python\\Python311\\Lib\\site-packages\\fyers_apiv3\\FyersWebsocket\\data_ws.py\", line 973, in __response_output\n    self.On_message(response)\n  File \"C:\\Users\\Sayan\\AppData\\Local\\Programs\\Python\\Python311\\Lib\\site-packages\\fyers_apiv3\\FyersWebsocket\\data_ws.py\", line 1403, in On_message\n    self.OnMessage(message)\n  File \"c:\\sayan's-project\\fyers\\fy_websocket.py\", line 11, in onmessage\n    print(message['symbol']+'= '+message['ltp'])\n          ~~~~~~~~~~~~~~~~~~~~~~^~~~~~~~~~~~~~~\nTypeError: can only concatenate str (not \"float\") to str","exception_name":"TypeError"}
{"level":"ERROR","location":"[__auth_resp:666] data_ws","message":"'symbol'","timestamp":"2023-08-19 21:17:38,747+0530","service":"FyersDataSocket","exception":"Traceback (most recent call last):\n  File \"C:\\Users\\Sayan\\AppData\\Local\\Programs\\Python\\Python311\\Lib\\site-packages\\fyers_apiv3\\FyersWebsocket\\data_ws.py\", line 643, in __auth_resp\n    self.On_message(\n  File \"C:\\Users\\Sayan\\AppData\\Local\\Programs\\Python\\Python311\\Lib\\site-packages\\fyers_apiv3\\FyersWebsocket\\data_ws.py\", line 1403, in On_message\n    self.OnMessage(message)\n  File \"c:\\sayan's-project\\fyers\\fy_websocket.py\", line 11, in onmessage\n    print(message['symbol'])\n          ~~~~~~~^^^^^^^^^^\nKeyError: 'symbol'","exception_name":"KeyError"}
{"level":"ERROR","location":"[__lite_full_mode_resp:823] data_ws","message":"'symbol'","timestamp":"2023-08-19 21:17:39,315+0530","service":"FyersDataSocket","exception":"Traceback (most recent call last):\n  File \"C:\\Users\\Sayan\\AppData\\Local\\Programs\\Python\\Python311\\Lib\\site-packages\\fyers_apiv3\\FyersWebsocket\\data_ws.py\", line 805, in __lite_full_mode_resp\n    self.On_message(\n  File \"C:\\Users\\Sayan\\AppData\\Local\\Programs\\Python\\Python311\\Lib\\site-packages\\fyers_apiv3\\FyersWebsocket\\data_ws.py\", line 1403, in On_message\n    self.OnMessage(message)\n  File \"c:\\sayan's-project\\fyers\\fy_websocket.py\", line 11, in onmessage\n    print(message['symbol'])\n          ~~~~~~~^^^^^^^^^^\nKeyError: 'symbol'","exception_name":"KeyError"}
{"level":"ERROR","location":"[__subscribe_resp:707] data_ws","message":"'symbol'","timestamp":"2023-08-19 21:17:40,903+0530","service":"FyersDataSocket","exception":"Traceback (most recent call last):\n  File \"C:\\Users\\Sayan\\AppData\\Local\\Programs\\Python\\Python311\\Lib\\site-packages\\fyers_apiv3\\FyersWebsocket\\data_ws.py\", line 688, in __subscribe_resp\n    self.On_message(\n  File \"C:\\Users\\Sayan\\AppData\\Local\\Programs\\Python\\Python311\\Lib\\site-packages\\fyers_apiv3\\FyersWebsocket\\data_ws.py\", line 1403, in On_message\n    self.OnMessage(message)\n  File \"c:\\sayan's-project\\fyers\\fy_websocket.py\", line 11, in onmessage\n    print(message['symbol'])\n          ~~~~~~~^^^^^^^^^^\nKeyError: 'symbol'","exception_name":"KeyError"}
{"level":"ERROR","location":"[__auth_resp:666] data_ws","message":"'symbol'","timestamp":"2023-08-19 21:18:51,318+0530","service":"FyersDataSocket","exception":"Traceback (most recent call last):\n  File \"C:\\Users\\Sayan\\AppData\\Local\\Programs\\Python\\Python311\\Lib\\site-packages\\fyers_apiv3\\FyersWebsocket\\data_ws.py\", line 643, in __auth_resp\n    self.On_message(\n  File \"C:\\Users\\Sayan\\AppData\\Local\\Programs\\Python\\Python311\\Lib\\site-packages\\fyers_apiv3\\FyersWebsocket\\data_ws.py\", line 1403, in On_message\n    self.OnMessage(message)\n  File \"c:\\sayan's-project\\fyers\\fy_websocket.py\", line 12, in onmessage\n    print(message['symbol']+'= '+message['ltp'])\n          ~~~~~~~^^^^^^^^^^\nKeyError: 'symbol'","exception_name":"KeyError"}
{"level":"ERROR","location":"[__lite_full_mode_resp:823] data_ws","message":"'symbol'","timestamp":"2023-08-19 21:18:51,887+0530","service":"FyersDataSocket","exception":"Traceback (most recent call last):\n  File \"C:\\Users\\Sayan\\AppData\\Local\\Programs\\Python\\Python311\\Lib\\site-packages\\fyers_apiv3\\FyersWebsocket\\data_ws.py\", line 805, in __lite_full_mode_resp\n    self.On_message(\n  File \"C:\\Users\\Sayan\\AppData\\Local\\Programs\\Python\\Python311\\Lib\\site-packages\\fyers_apiv3\\FyersWebsocket\\data_ws.py\", line 1403, in On_message\n    self.OnMessage(message)\n  File \"c:\\sayan's-project\\fyers\\fy_websocket.py\", line 12, in onmessage\n    print(message['symbol']+'= '+message['ltp'])\n          ~~~~~~~^^^^^^^^^^\nKeyError: 'symbol'","exception_name":"KeyError"}
{"level":"ERROR","location":"[__subscribe_resp:707] data_ws","message":"'symbol'","timestamp":"2023-08-19 21:18:53,608+0530","service":"FyersDataSocket","exception":"Traceback (most recent call last):\n  File \"C:\\Users\\Sayan\\AppData\\Local\\Programs\\Python\\Python311\\Lib\\site-packages\\fyers_apiv3\\FyersWebsocket\\data_ws.py\", line 688, in __subscribe_resp\n    self.On_message(\n  File \"C:\\Users\\Sayan\\AppData\\Local\\Programs\\Python\\Python311\\Lib\\site-packages\\fyers_apiv3\\FyersWebsocket\\data_ws.py\", line 1403, in On_message\n    self.OnMessage(message)\n  File \"c:\\sayan's-project\\fyers\\fy_websocket.py\", line 12, in onmessage\n    print(message['symbol']+'= '+message['ltp'])\n          ~~~~~~~^^^^^^^^^^\nKeyError: 'symbol'","exception_name":"KeyError"}
{"level":"ERROR","location":"[__response_output:976] data_ws","message":"can only concatenate str (not \"float\") to str","timestamp":"2023-08-19 21:18:53,941+0530","service":"FyersDataSocket","exception":"Traceback (most recent call last):\n  File \"C:\\Users\\Sayan\\AppData\\Local\\Programs\\Python\\Python311\\Lib\\site-packages\\fyers_apiv3\\FyersWebsocket\\data_ws.py\", line 973, in __response_output\n    self.On_message(response)\n  File \"C:\\Users\\Sayan\\AppData\\Local\\Programs\\Python\\Python311\\Lib\\site-packages\\fyers_apiv3\\FyersWebsocket\\data_ws.py\", line 1403, in On_message\n    self.OnMessage(message)\n  File \"c:\\sayan's-project\\fyers\\fy_websocket.py\", line 12, in onmessage\n    print(message['symbol']+'= '+message['ltp'])\n          ~~~~~~~~~~~~~~~~~~~~~~^~~~~~~~~~~~~~~\nTypeError: can only concatenate str (not \"float\") to str","exception_name":"TypeError"}
{"level":"ERROR","location":"[__response_output:976] data_ws","message":"can only concatenate str (not \"float\") to str","timestamp":"2023-08-19 21:18:54,034+0530","service":"FyersDataSocket","exception":"Traceback (most recent call last):\n  File \"C:\\Users\\Sayan\\AppData\\Local\\Programs\\Python\\Python311\\Lib\\site-packages\\fyers_apiv3\\FyersWebsocket\\data_ws.py\", line 973, in __response_output\n    self.On_message(response)\n  File \"C:\\Users\\Sayan\\AppData\\Local\\Programs\\Python\\Python311\\Lib\\site-packages\\fyers_apiv3\\FyersWebsocket\\data_ws.py\", line 1403, in On_message\n    self.OnMessage(message)\n  File \"c:\\sayan's-project\\fyers\\fy_websocket.py\", line 12, in onmessage\n    print(message['symbol']+'= '+message['ltp'])\n          ~~~~~~~~~~~~~~~~~~~~~~^~~~~~~~~~~~~~~\nTypeError: can only concatenate str (not \"float\") to str","exception_name":"TypeError"}
{"level":"ERROR","location":"[__auth_resp:666] data_ws","message":"'symbol'","timestamp":"2023-08-19 21:19:14,074+0530","service":"FyersDataSocket","exception":"Traceback (most recent call last):\n  File \"C:\\Users\\Sayan\\AppData\\Local\\Programs\\Python\\Python311\\Lib\\site-packages\\fyers_apiv3\\FyersWebsocket\\data_ws.py\", line 643, in __auth_resp\n    self.On_message(\n  File \"C:\\Users\\Sayan\\AppData\\Local\\Programs\\Python\\Python311\\Lib\\site-packages\\fyers_apiv3\\FyersWebsocket\\data_ws.py\", line 1403, in On_message\n    self.OnMessage(message)\n  File \"c:\\sayan's-project\\fyers\\fy_websocket.py\", line 11, in onmessage\n    print(message['symbol'])\n          ~~~~~~~^^^^^^^^^^\nKeyError: 'symbol'","exception_name":"KeyError"}
{"level":"ERROR","location":"[__lite_full_mode_resp:823] data_ws","message":"'symbol'","timestamp":"2023-08-19 21:19:14,643+0530","service":"FyersDataSocket","exception":"Traceback (most recent call last):\n  File \"C:\\Users\\Sayan\\AppData\\Local\\Programs\\Python\\Python311\\Lib\\site-packages\\fyers_apiv3\\FyersWebsocket\\data_ws.py\", line 805, in __lite_full_mode_resp\n    self.On_message(\n  File \"C:\\Users\\Sayan\\AppData\\Local\\Programs\\Python\\Python311\\Lib\\site-packages\\fyers_apiv3\\FyersWebsocket\\data_ws.py\", line 1403, in On_message\n    self.OnMessage(message)\n  File \"c:\\sayan's-project\\fyers\\fy_websocket.py\", line 11, in onmessage\n    print(message['symbol'])\n          ~~~~~~~^^^^^^^^^^\nKeyError: 'symbol'","exception_name":"KeyError"}
{"level":"ERROR","location":"[__subscribe_resp:707] data_ws","message":"'symbol'","timestamp":"2023-08-19 21:19:16,222+0530","service":"FyersDataSocket","exception":"Traceback (most recent call last):\n  File \"C:\\Users\\Sayan\\AppData\\Local\\Programs\\Python\\Python311\\Lib\\site-packages\\fyers_apiv3\\FyersWebsocket\\data_ws.py\", line 688, in __subscribe_resp\n    self.On_message(\n  File \"C:\\Users\\Sayan\\AppData\\Local\\Programs\\Python\\Python311\\Lib\\site-packages\\fyers_apiv3\\FyersWebsocket\\data_ws.py\", line 1403, in On_message\n    self.OnMessage(message)\n  File \"c:\\sayan's-project\\fyers\\fy_websocket.py\", line 11, in onmessage\n    print(message['symbol'])\n          ~~~~~~~^^^^^^^^^^\nKeyError: 'symbol'","exception_name":"KeyError"}
{"level":"ERROR","location":"[__response_output:976] data_ws","message":"can only concatenate str (not \"float\") to str","timestamp":"2023-08-19 21:19:16,714+0530","service":"FyersDataSocket","exception":"Traceback (most recent call last):\n  File \"C:\\Users\\Sayan\\AppData\\Local\\Programs\\Python\\Python311\\Lib\\site-packages\\fyers_apiv3\\FyersWebsocket\\data_ws.py\", line 973, in __response_output\n    self.On_message(response)\n  File \"C:\\Users\\Sayan\\AppData\\Local\\Programs\\Python\\Python311\\Lib\\site-packages\\fyers_apiv3\\FyersWebsocket\\data_ws.py\", line 1403, in On_message\n    self.OnMessage(message)\n  File \"c:\\sayan's-project\\fyers\\fy_websocket.py\", line 13, in onmessage\n    print(message['symbol']+'= '+message['ltp'])\n          ~~~~~~~~~~~~~~~~~~~~~~^~~~~~~~~~~~~~~\nTypeError: can only concatenate str (not \"float\") to str","exception_name":"TypeError"}
{"level":"ERROR","location":"[__response_output:976] data_ws","message":"can only concatenate str (not \"float\") to str","timestamp":"2023-08-19 21:19:16,715+0530","service":"FyersDataSocket","exception":"Traceback (most recent call last):\n  File \"C:\\Users\\Sayan\\AppData\\Local\\Programs\\Python\\Python311\\Lib\\site-packages\\fyers_apiv3\\FyersWebsocket\\data_ws.py\", line 973, in __response_output\n    self.On_message(response)\n  File \"C:\\Users\\Sayan\\AppData\\Local\\Programs\\Python\\Python311\\Lib\\site-packages\\fyers_apiv3\\FyersWebsocket\\data_ws.py\", line 1403, in On_message\n    self.OnMessage(message)\n  File \"c:\\sayan's-project\\fyers\\fy_websocket.py\", line 13, in onmessage\n    print(message['symbol']+'= '+message['ltp'])\n          ~~~~~~~~~~~~~~~~~~~~~~^~~~~~~~~~~~~~~\nTypeError: can only concatenate str (not \"float\") to str","exception_name":"TypeError"}
{"level":"ERROR","location":"[__auth_resp:666] data_ws","message":"'symbol'","timestamp":"2023-08-19 21:19:38,823+0530","service":"FyersDataSocket","exception":"Traceback (most recent call last):\n  File \"C:\\Users\\Sayan\\AppData\\Local\\Programs\\Python\\Python311\\Lib\\site-packages\\fyers_apiv3\\FyersWebsocket\\data_ws.py\", line 643, in __auth_resp\n    self.On_message(\n  File \"C:\\Users\\Sayan\\AppData\\Local\\Programs\\Python\\Python311\\Lib\\site-packages\\fyers_apiv3\\FyersWebsocket\\data_ws.py\", line 1403, in On_message\n    self.OnMessage(message)\n  File \"c:\\sayan's-project\\fyers\\fy_websocket.py\", line 9, in onmessage\n    print(message['symbol'])\n          ~~~~~~~^^^^^^^^^^\nKeyError: 'symbol'","exception_name":"KeyError"}
{"level":"ERROR","location":"[__lite_full_mode_resp:823] data_ws","message":"'symbol'","timestamp":"2023-08-19 21:19:39,392+0530","service":"FyersDataSocket","exception":"Traceback (most recent call last):\n  File \"C:\\Users\\Sayan\\AppData\\Local\\Programs\\Python\\Python311\\Lib\\site-packages\\fyers_apiv3\\FyersWebsocket\\data_ws.py\", line 805, in __lite_full_mode_resp\n    self.On_message(\n  File \"C:\\Users\\Sayan\\AppData\\Local\\Programs\\Python\\Python311\\Lib\\site-packages\\fyers_apiv3\\FyersWebsocket\\data_ws.py\", line 1403, in On_message\n    self.OnMessage(message)\n  File \"c:\\sayan's-project\\fyers\\fy_websocket.py\", line 9, in onmessage\n    print(message['symbol'])\n          ~~~~~~~^^^^^^^^^^\nKeyError: 'symbol'","exception_name":"KeyError"}
{"level":"ERROR","location":"[__subscribe_resp:707] data_ws","message":"'symbol'","timestamp":"2023-08-19 21:19:41,039+0530","service":"FyersDataSocket","exception":"Traceback (most recent call last):\n  File \"C:\\Users\\Sayan\\AppData\\Local\\Programs\\Python\\Python311\\Lib\\site-packages\\fyers_apiv3\\FyersWebsocket\\data_ws.py\", line 688, in __subscribe_resp\n    self.On_message(\n  File \"C:\\Users\\Sayan\\AppData\\Local\\Programs\\Python\\Python311\\Lib\\site-packages\\fyers_apiv3\\FyersWebsocket\\data_ws.py\", line 1403, in On_message\n    self.OnMessage(message)\n  File \"c:\\sayan's-project\\fyers\\fy_websocket.py\", line 9, in onmessage\n    print(message['symbol'])\n          ~~~~~~~^^^^^^^^^^\nKeyError: 'symbol'","exception_name":"KeyError"}
{"level":"ERROR","location":"[__response_output:976] data_ws","message":"can only concatenate str (not \"float\") to str","timestamp":"2023-08-19 21:19:41,325+0530","service":"FyersDataSocket","exception":"Traceback (most recent call last):\n  File \"C:\\Users\\Sayan\\AppData\\Local\\Programs\\Python\\Python311\\Lib\\site-packages\\fyers_apiv3\\FyersWebsocket\\data_ws.py\", line 973, in __response_output\n    self.On_message(response)\n  File \"C:\\Users\\Sayan\\AppData\\Local\\Programs\\Python\\Python311\\Lib\\site-packages\\fyers_apiv3\\FyersWebsocket\\data_ws.py\", line 1403, in On_message\n    self.OnMessage(message)\n  File \"c:\\sayan's-project\\fyers\\fy_websocket.py\", line 11, in onmessage\n    print(message['symbol'] + '= ' + message['ltp'])\n          ~~~~~~~~~~~~~~~~~~~~~~~~~^~~~~~~~~~~~~~~~\nTypeError: can only concatenate str (not \"float\") to str","exception_name":"TypeError"}
{"level":"ERROR","location":"[__response_output:976] data_ws","message":"can only concatenate str (not \"float\") to str","timestamp":"2023-08-19 21:19:41,357+0530","service":"FyersDataSocket","exception":"Traceback (most recent call last):\n  File \"C:\\Users\\Sayan\\AppData\\Local\\Programs\\Python\\Python311\\Lib\\site-packages\\fyers_apiv3\\FyersWebsocket\\data_ws.py\", line 973, in __response_output\n    self.On_message(response)\n  File \"C:\\Users\\Sayan\\AppData\\Local\\Programs\\Python\\Python311\\Lib\\site-packages\\fyers_apiv3\\FyersWebsocket\\data_ws.py\", line 1403, in On_message\n    self.OnMessage(message)\n  File \"c:\\sayan's-project\\fyers\\fy_websocket.py\", line 11, in onmessage\n    print(message['symbol'] + '= ' + message['ltp'])\n          ~~~~~~~~~~~~~~~~~~~~~~~~~^~~~~~~~~~~~~~~~\nTypeError: can only concatenate str (not \"float\") to str","exception_name":"TypeError"}
{"level":"ERROR","location":"[__auth_resp:666] data_ws","message":"'symbol'","timestamp":"2023-08-19 21:20:19,998+0530","service":"FyersDataSocket","exception":"Traceback (most recent call last):\n  File \"C:\\Users\\Sayan\\AppData\\Local\\Programs\\Python\\Python311\\Lib\\site-packages\\fyers_apiv3\\FyersWebsocket\\data_ws.py\", line 643, in __auth_resp\n    self.On_message(\n  File \"C:\\Users\\Sayan\\AppData\\Local\\Programs\\Python\\Python311\\Lib\\site-packages\\fyers_apiv3\\FyersWebsocket\\data_ws.py\", line 1403, in On_message\n    self.OnMessage(message)\n  File \"c:\\sayan's-project\\fyers\\fy_websocket.py\", line 9, in onmessage\n    mm = message['symbol'] + '= ' + message['ltp']\n         ~~~~~~~^^^^^^^^^^\nKeyError: 'symbol'","exception_name":"KeyError"}
{"level":"ERROR","location":"[__lite_full_mode_resp:823] data_ws","message":"'symbol'","timestamp":"2023-08-19 21:20:20,568+0530","service":"FyersDataSocket","exception":"Traceback (most recent call last):\n  File \"C:\\Users\\Sayan\\AppData\\Local\\Programs\\Python\\Python311\\Lib\\site-packages\\fyers_apiv3\\FyersWebsocket\\data_ws.py\", line 805, in __lite_full_mode_resp\n    self.On_message(\n  File \"C:\\Users\\Sayan\\AppData\\Local\\Programs\\Python\\Python311\\Lib\\site-packages\\fyers_apiv3\\FyersWebsocket\\data_ws.py\", line 1403, in On_message\n    self.OnMessage(message)\n  File \"c:\\sayan's-project\\fyers\\fy_websocket.py\", line 9, in onmessage\n    mm = message['symbol'] + '= ' + message['ltp']\n         ~~~~~~~^^^^^^^^^^\nKeyError: 'symbol'","exception_name":"KeyError"}
{"level":"ERROR","location":"[__subscribe_resp:707] data_ws","message":"'symbol'","timestamp":"2023-08-19 21:20:22,916+0530","service":"FyersDataSocket","exception":"Traceback (most recent call last):\n  File \"C:\\Users\\Sayan\\AppData\\Local\\Programs\\Python\\Python311\\Lib\\site-packages\\fyers_apiv3\\FyersWebsocket\\data_ws.py\", line 688, in __subscribe_resp\n    self.On_message(\n  File \"C:\\Users\\Sayan\\AppData\\Local\\Programs\\Python\\Python311\\Lib\\site-packages\\fyers_apiv3\\FyersWebsocket\\data_ws.py\", line 1403, in On_message\n    self.OnMessage(message)\n  File \"c:\\sayan's-project\\fyers\\fy_websocket.py\", line 9, in onmessage\n    mm = message['symbol'] + '= ' + message['ltp']\n         ~~~~~~~^^^^^^^^^^\nKeyError: 'symbol'","exception_name":"KeyError"}
{"level":"ERROR","location":"[__response_output:976] data_ws","message":"can only concatenate str (not \"float\") to str","timestamp":"2023-08-19 21:20:23,069+0530","service":"FyersDataSocket","exception":"Traceback (most recent call last):\n  File \"C:\\Users\\Sayan\\AppData\\Local\\Programs\\Python\\Python311\\Lib\\site-packages\\fyers_apiv3\\FyersWebsocket\\data_ws.py\", line 973, in __response_output\n    self.On_message(response)\n  File \"C:\\Users\\Sayan\\AppData\\Local\\Programs\\Python\\Python311\\Lib\\site-packages\\fyers_apiv3\\FyersWebsocket\\data_ws.py\", line 1403, in On_message\n    self.OnMessage(message)\n  File \"c:\\sayan's-project\\fyers\\fy_websocket.py\", line 9, in onmessage\n    mm = message['symbol'] + '= ' + message['ltp']\n         ~~~~~~~~~~~~~~~~~~~~~~~~~^~~~~~~~~~~~~~~~\nTypeError: can only concatenate str (not \"float\") to str","exception_name":"TypeError"}
{"level":"ERROR","location":"[__response_output:976] data_ws","message":"can only concatenate str (not \"float\") to str","timestamp":"2023-08-19 21:20:23,147+0530","service":"FyersDataSocket","exception":"Traceback (most recent call last):\n  File \"C:\\Users\\Sayan\\AppData\\Local\\Programs\\Python\\Python311\\Lib\\site-packages\\fyers_apiv3\\FyersWebsocket\\data_ws.py\", line 973, in __response_output\n    self.On_message(response)\n  File \"C:\\Users\\Sayan\\AppData\\Local\\Programs\\Python\\Python311\\Lib\\site-packages\\fyers_apiv3\\FyersWebsocket\\data_ws.py\", line 1403, in On_message\n    self.OnMessage(message)\n  File \"c:\\sayan's-project\\fyers\\fy_websocket.py\", line 9, in onmessage\n    mm = message['symbol'] + '= ' + message['ltp']\n         ~~~~~~~~~~~~~~~~~~~~~~~~~^~~~~~~~~~~~~~~~\nTypeError: can only concatenate str (not \"float\") to str","exception_name":"TypeError"}
{"level":"ERROR","location":"[__auth_resp:666] data_ws","message":"'symbol'","timestamp":"2023-08-19 21:22:58,163+0530","service":"FyersDataSocket","exception":"Traceback (most recent call last):\n  File \"C:\\Users\\Sayan\\AppData\\Local\\Programs\\Python\\Python311\\Lib\\site-packages\\fyers_apiv3\\FyersWebsocket\\data_ws.py\", line 643, in __auth_resp\n    self.On_message(\n  File \"C:\\Users\\Sayan\\AppData\\Local\\Programs\\Python\\Python311\\Lib\\site-packages\\fyers_apiv3\\FyersWebsocket\\data_ws.py\", line 1403, in On_message\n    self.OnMessage(message)\n  File \"c:\\sayan's-project\\fyers\\fy_websocket.py\", line 8, in onmessage\n    m = message['symbol']\n        ~~~~~~~^^^^^^^^^^\nKeyError: 'symbol'","exception_name":"KeyError"}
{"level":"ERROR","location":"[__lite_full_mode_resp:823] data_ws","message":"'symbol'","timestamp":"2023-08-19 21:22:58,731+0530","service":"FyersDataSocket","exception":"Traceback (most recent call last):\n  File \"C:\\Users\\Sayan\\AppData\\Local\\Programs\\Python\\Python311\\Lib\\site-packages\\fyers_apiv3\\FyersWebsocket\\data_ws.py\", line 805, in __lite_full_mode_resp\n    self.On_message(\n  File \"C:\\Users\\Sayan\\AppData\\Local\\Programs\\Python\\Python311\\Lib\\site-packages\\fyers_apiv3\\FyersWebsocket\\data_ws.py\", line 1403, in On_message\n    self.OnMessage(message)\n  File \"c:\\sayan's-project\\fyers\\fy_websocket.py\", line 8, in onmessage\n    m = message['symbol']\n        ~~~~~~~^^^^^^^^^^\nKeyError: 'symbol'","exception_name":"KeyError"}
{"level":"ERROR","location":"[__subscribe_resp:707] data_ws","message":"'symbol'","timestamp":"2023-08-19 21:23:00,779+0530","service":"FyersDataSocket","exception":"Traceback (most recent call last):\n  File \"C:\\Users\\Sayan\\AppData\\Local\\Programs\\Python\\Python311\\Lib\\site-packages\\fyers_apiv3\\FyersWebsocket\\data_ws.py\", line 688, in __subscribe_resp\n    self.On_message(\n  File \"C:\\Users\\Sayan\\AppData\\Local\\Programs\\Python\\Python311\\Lib\\site-packages\\fyers_apiv3\\FyersWebsocket\\data_ws.py\", line 1403, in On_message\n    self.OnMessage(message)\n  File \"c:\\sayan's-project\\fyers\\fy_websocket.py\", line 8, in onmessage\n    m = message['symbol']\n        ~~~~~~~^^^^^^^^^^\nKeyError: 'symbol'","exception_name":"KeyError"}
{"level":"ERROR","location":"[__response_output:976] data_ws","message":"can only concatenate str (not \"float\") to str","timestamp":"2023-08-19 21:23:01,188+0530","service":"FyersDataSocket","exception":"Traceback (most recent call last):\n  File \"C:\\Users\\Sayan\\AppData\\Local\\Programs\\Python\\Python311\\Lib\\site-packages\\fyers_apiv3\\FyersWebsocket\\data_ws.py\", line 973, in __response_output\n    self.On_message(response)\n  File \"C:\\Users\\Sayan\\AppData\\Local\\Programs\\Python\\Python311\\Lib\\site-packages\\fyers_apiv3\\FyersWebsocket\\data_ws.py\", line 1403, in On_message\n    self.OnMessage(message)\n  File \"c:\\sayan's-project\\fyers\\fy_websocket.py\", line 12, in onmessage\n    print(m+p)\n          ~^~\nTypeError: can only concatenate str (not \"float\") to str","exception_name":"TypeError"}
{"level":"ERROR","location":"[__response_output:976] data_ws","message":"can only concatenate str (not \"float\") to str","timestamp":"2023-08-19 21:23:01,218+0530","service":"FyersDataSocket","exception":"Traceback (most recent call last):\n  File \"C:\\Users\\Sayan\\AppData\\Local\\Programs\\Python\\Python311\\Lib\\site-packages\\fyers_apiv3\\FyersWebsocket\\data_ws.py\", line 973, in __response_output\n    self.On_message(response)\n  File \"C:\\Users\\Sayan\\AppData\\Local\\Programs\\Python\\Python311\\Lib\\site-packages\\fyers_apiv3\\FyersWebsocket\\data_ws.py\", line 1403, in On_message\n    self.OnMessage(message)\n  File \"c:\\sayan's-project\\fyers\\fy_websocket.py\", line 12, in onmessage\n    print(m+p)\n          ~^~\nTypeError: can only concatenate str (not \"float\") to str","exception_name":"TypeError"}
{"level":"ERROR","location":"[__auth_resp:666] data_ws","message":"'symbol'","timestamp":"2023-08-19 21:23:12,757+0530","service":"FyersDataSocket","exception":"Traceback (most recent call last):\n  File \"C:\\Users\\Sayan\\AppData\\Local\\Programs\\Python\\Python311\\Lib\\site-packages\\fyers_apiv3\\FyersWebsocket\\data_ws.py\", line 643, in __auth_resp\n    self.On_message(\n  File \"C:\\Users\\Sayan\\AppData\\Local\\Programs\\Python\\Python311\\Lib\\site-packages\\fyers_apiv3\\FyersWebsocket\\data_ws.py\", line 1403, in On_message\n    self.OnMessage(message)\n  File \"c:\\sayan's-project\\fyers\\fy_websocket.py\", line 8, in onmessage\n    m = message['symbol']\n        ~~~~~~~^^^^^^^^^^\nKeyError: 'symbol'","exception_name":"KeyError"}
{"level":"ERROR","location":"[__lite_full_mode_resp:823] data_ws","message":"'symbol'","timestamp":"2023-08-19 21:23:13,369+0530","service":"FyersDataSocket","exception":"Traceback (most recent call last):\n  File \"C:\\Users\\Sayan\\AppData\\Local\\Programs\\Python\\Python311\\Lib\\site-packages\\fyers_apiv3\\FyersWebsocket\\data_ws.py\", line 805, in __lite_full_mode_resp\n    self.On_message(\n  File \"C:\\Users\\Sayan\\AppData\\Local\\Programs\\Python\\Python311\\Lib\\site-packages\\fyers_apiv3\\FyersWebsocket\\data_ws.py\", line 1403, in On_message\n    self.OnMessage(message)\n  File \"c:\\sayan's-project\\fyers\\fy_websocket.py\", line 8, in onmessage\n    m = message['symbol']\n        ~~~~~~~^^^^^^^^^^\nKeyError: 'symbol'","exception_name":"KeyError"}
{"level":"ERROR","location":"[__subscribe_resp:707] data_ws","message":"'symbol'","timestamp":"2023-08-19 21:23:13,998+0530","service":"FyersDataSocket","exception":"Traceback (most recent call last):\n  File \"C:\\Users\\Sayan\\AppData\\Local\\Programs\\Python\\Python311\\Lib\\site-packages\\fyers_apiv3\\FyersWebsocket\\data_ws.py\", line 688, in __subscribe_resp\n    self.On_message(\n  File \"C:\\Users\\Sayan\\AppData\\Local\\Programs\\Python\\Python311\\Lib\\site-packages\\fyers_apiv3\\FyersWebsocket\\data_ws.py\", line 1403, in On_message\n    self.OnMessage(message)\n  File \"c:\\sayan's-project\\fyers\\fy_websocket.py\", line 8, in onmessage\n    m = message['symbol']\n        ~~~~~~~^^^^^^^^^^\nKeyError: 'symbol'","exception_name":"KeyError"}
{"level":"ERROR","location":"[__auth_resp:666] data_ws","message":"'symbol'","timestamp":"2023-08-19 22:56:24,918+0530","service":"FyersDataSocket","exception":"Traceback (most recent call last):\n  File \"C:\\Users\\Sayan\\AppData\\Local\\Programs\\Python\\Python311\\Lib\\site-packages\\fyers_apiv3\\FyersWebsocket\\data_ws.py\", line 643, in __auth_resp\n    self.On_message(\n  File \"C:\\Users\\Sayan\\AppData\\Local\\Programs\\Python\\Python311\\Lib\\site-packages\\fyers_apiv3\\FyersWebsocket\\data_ws.py\", line 1403, in On_message\n    self.OnMessage(message)\n  File \"c:\\sayan's-project\\fyers\\fy_websocket.py\", line 9, in onmessage\n    print(message['symbol'])\n          ~~~~~~~^^^^^^^^^^\nKeyError: 'symbol'","exception_name":"KeyError"}
{"level":"ERROR","location":"[__lite_full_mode_resp:823] data_ws","message":"'symbol'","timestamp":"2023-08-19 22:56:25,454+0530","service":"FyersDataSocket","exception":"Traceback (most recent call last):\n  File \"C:\\Users\\Sayan\\AppData\\Local\\Programs\\Python\\Python311\\Lib\\site-packages\\fyers_apiv3\\FyersWebsocket\\data_ws.py\", line 805, in __lite_full_mode_resp\n    self.On_message(\n  File \"C:\\Users\\Sayan\\AppData\\Local\\Programs\\Python\\Python311\\Lib\\site-packages\\fyers_apiv3\\FyersWebsocket\\data_ws.py\", line 1403, in On_message\n    self.OnMessage(message)\n  File \"c:\\sayan's-project\\fyers\\fy_websocket.py\", line 9, in onmessage\n    print(message['symbol'])\n          ~~~~~~~^^^^^^^^^^\nKeyError: 'symbol'","exception_name":"KeyError"}
{"level":"ERROR","location":"[__subscribe_resp:707] data_ws","message":"'symbol'","timestamp":"2023-08-19 22:56:27,453+0530","service":"FyersDataSocket","exception":"Traceback (most recent call last):\n  File \"C:\\Users\\Sayan\\AppData\\Local\\Programs\\Python\\Python311\\Lib\\site-packages\\fyers_apiv3\\FyersWebsocket\\data_ws.py\", line 688, in __subscribe_resp\n    self.On_message(\n  File \"C:\\Users\\Sayan\\AppData\\Local\\Programs\\Python\\Python311\\Lib\\site-packages\\fyers_apiv3\\FyersWebsocket\\data_ws.py\", line 1403, in On_message\n    self.OnMessage(message)\n  File \"c:\\sayan's-project\\fyers\\fy_websocket.py\", line 9, in onmessage\n    print(message['symbol'])\n          ~~~~~~~^^^^^^^^^^\nKeyError: 'symbol'","exception_name":"KeyError"}
{"level":"ERROR","location":"[__auth_resp:666] data_ws","message":"'symbol'","timestamp":"2023-08-19 22:56:43,008+0530","service":"FyersDataSocket","exception":"Traceback (most recent call last):\n  File \"C:\\Users\\Sayan\\AppData\\Local\\Programs\\Python\\Python311\\Lib\\site-packages\\fyers_apiv3\\FyersWebsocket\\data_ws.py\", line 643, in __auth_resp\n    self.On_message(\n  File \"C:\\Users\\Sayan\\AppData\\Local\\Programs\\Python\\Python311\\Lib\\site-packages\\fyers_apiv3\\FyersWebsocket\\data_ws.py\", line 1403, in On_message\n    self.OnMessage(message)\n  File \"c:\\sayan's-project\\fyers\\fy_websocket.py\", line 9, in onmessage\n    print(message['symbol'])\n          ~~~~~~~^^^^^^^^^^\nKeyError: 'symbol'","exception_name":"KeyError"}
{"level":"ERROR","location":"[__lite_full_mode_resp:823] data_ws","message":"'symbol'","timestamp":"2023-08-19 22:56:43,578+0530","service":"FyersDataSocket","exception":"Traceback (most recent call last):\n  File \"C:\\Users\\Sayan\\AppData\\Local\\Programs\\Python\\Python311\\Lib\\site-packages\\fyers_apiv3\\FyersWebsocket\\data_ws.py\", line 805, in __lite_full_mode_resp\n    self.On_message(\n  File \"C:\\Users\\Sayan\\AppData\\Local\\Programs\\Python\\Python311\\Lib\\site-packages\\fyers_apiv3\\FyersWebsocket\\data_ws.py\", line 1403, in On_message\n    self.OnMessage(message)\n  File \"c:\\sayan's-project\\fyers\\fy_websocket.py\", line 9, in onmessage\n    print(message['symbol'])\n          ~~~~~~~^^^^^^^^^^\nKeyError: 'symbol'","exception_name":"KeyError"}
{"level":"ERROR","location":"[__subscribe_resp:707] data_ws","message":"'symbol'","timestamp":"2023-08-19 22:56:45,573+0530","service":"FyersDataSocket","exception":"Traceback (most recent call last):\n  File \"C:\\Users\\Sayan\\AppData\\Local\\Programs\\Python\\Python311\\Lib\\site-packages\\fyers_apiv3\\FyersWebsocket\\data_ws.py\", line 688, in __subscribe_resp\n    self.On_message(\n  File \"C:\\Users\\Sayan\\AppData\\Local\\Programs\\Python\\Python311\\Lib\\site-packages\\fyers_apiv3\\FyersWebsocket\\data_ws.py\", line 1403, in On_message\n    self.OnMessage(message)\n  File \"c:\\sayan's-project\\fyers\\fy_websocket.py\", line 9, in onmessage\n    print(message['symbol'])\n          ~~~~~~~^^^^^^^^^^\nKeyError: 'symbol'","exception_name":"KeyError"}
{"level":"ERROR","location":"[__unsubscribe_resp:761] data_ws","message":"'symbol'","timestamp":"2023-08-19 22:56:47,970+0530","service":"FyersDataSocket","exception":"Traceback (most recent call last):\n  File \"C:\\Users\\Sayan\\AppData\\Local\\Programs\\Python\\Python311\\Lib\\site-packages\\fyers_apiv3\\FyersWebsocket\\data_ws.py\", line 730, in __unsubscribe_resp\n    self.On_message(\n  File \"C:\\Users\\Sayan\\AppData\\Local\\Programs\\Python\\Python311\\Lib\\site-packages\\fyers_apiv3\\FyersWebsocket\\data_ws.py\", line 1403, in On_message\n    self.OnMessage(message)\n  File \"c:\\sayan's-project\\fyers\\fy_websocket.py\", line 9, in onmessage\n    print(message['symbol'])\n          ~~~~~~~^^^^^^^^^^\nKeyError: 'symbol'","exception_name":"KeyError"}
{"level":"ERROR","location":"[__auth_resp:666] data_ws","message":"'symbol'","timestamp":"2023-08-19 22:57:28,089+0530","service":"FyersDataSocket","exception":"Traceback (most recent call last):\n  File \"C:\\Users\\Sayan\\AppData\\Local\\Programs\\Python\\Python311\\Lib\\site-packages\\fyers_apiv3\\FyersWebsocket\\data_ws.py\", line 643, in __auth_resp\n    self.On_message(\n  File \"C:\\Users\\Sayan\\AppData\\Local\\Programs\\Python\\Python311\\Lib\\site-packages\\fyers_apiv3\\FyersWebsocket\\data_ws.py\", line 1403, in On_message\n    self.OnMessage(message)\n  File \"c:\\sayan's-project\\fyers\\fy_websocket.py\", line 9, in onmessage\n    print(message['symbol'])\n          ~~~~~~~^^^^^^^^^^\nKeyError: 'symbol'","exception_name":"KeyError"}
{"level":"ERROR","location":"[__lite_full_mode_resp:823] data_ws","message":"'symbol'","timestamp":"2023-08-19 22:57:28,624+0530","service":"FyersDataSocket","exception":"Traceback (most recent call last):\n  File \"C:\\Users\\Sayan\\AppData\\Local\\Programs\\Python\\Python311\\Lib\\site-packages\\fyers_apiv3\\FyersWebsocket\\data_ws.py\", line 805, in __lite_full_mode_resp\n    self.On_message(\n  File \"C:\\Users\\Sayan\\AppData\\Local\\Programs\\Python\\Python311\\Lib\\site-packages\\fyers_apiv3\\FyersWebsocket\\data_ws.py\", line 1403, in On_message\n    self.OnMessage(message)\n  File \"c:\\sayan's-project\\fyers\\fy_websocket.py\", line 9, in onmessage\n    print(message['symbol'])\n          ~~~~~~~^^^^^^^^^^\nKeyError: 'symbol'","exception_name":"KeyError"}
{"level":"ERROR","location":"[__subscribe_resp:707] data_ws","message":"'symbol'","timestamp":"2023-08-19 22:57:30,273+0530","service":"FyersDataSocket","exception":"Traceback (most recent call last):\n  File \"C:\\Users\\Sayan\\AppData\\Local\\Programs\\Python\\Python311\\Lib\\site-packages\\fyers_apiv3\\FyersWebsocket\\data_ws.py\", line 688, in __subscribe_resp\n    self.On_message(\n  File \"C:\\Users\\Sayan\\AppData\\Local\\Programs\\Python\\Python311\\Lib\\site-packages\\fyers_apiv3\\FyersWebsocket\\data_ws.py\", line 1403, in On_message\n    self.OnMessage(message)\n  File \"c:\\sayan's-project\\fyers\\fy_websocket.py\", line 9, in onmessage\n    print(message['symbol'])\n          ~~~~~~~^^^^^^^^^^\nKeyError: 'symbol'","exception_name":"KeyError"}
{"level":"ERROR","location":"[__response_output:976] data_ws","message":"cannot access local variable 'data_type' where it is not associated with a value","timestamp":"2023-08-19 22:57:31,504+0530","service":"FyersDataSocket","exception":"Traceback (most recent call last):\n  File \"C:\\Users\\Sayan\\AppData\\Local\\Programs\\Python\\Python311\\Lib\\site-packages\\fyers_apiv3\\FyersWebsocket\\data_ws.py\", line 973, in __response_output\n    self.On_message(response)\n  File \"C:\\Users\\Sayan\\AppData\\Local\\Programs\\Python\\Python311\\Lib\\site-packages\\fyers_apiv3\\FyersWebsocket\\data_ws.py\", line 1403, in On_message\n    self.OnMessage(message)\n  File \"c:\\sayan's-project\\fyers\\fy_websocket.py\", line 19, in onmessage\n    fyers.subscribe(symbols=symbols, data_type=data_type)\n                                               ^^^^^^^^^\nUnboundLocalError: cannot access local variable 'data_type' where it is not associated with a value","exception_name":"UnboundLocalError"}
{"level":"ERROR","location":"[__unsubscribe_resp:761] data_ws","message":"'symbol'","timestamp":"2023-08-19 22:57:31,534+0530","service":"FyersDataSocket","exception":"Traceback (most recent call last):\n  File \"C:\\Users\\Sayan\\AppData\\Local\\Programs\\Python\\Python311\\Lib\\site-packages\\fyers_apiv3\\FyersWebsocket\\data_ws.py\", line 730, in __unsubscribe_resp\n    self.On_message(\n  File \"C:\\Users\\Sayan\\AppData\\Local\\Programs\\Python\\Python311\\Lib\\site-packages\\fyers_apiv3\\FyersWebsocket\\data_ws.py\", line 1403, in On_message\n    self.OnMessage(message)\n  File \"c:\\sayan's-project\\fyers\\fy_websocket.py\", line 9, in onmessage\n    print(message['symbol'])\n          ~~~~~~~^^^^^^^^^^\nKeyError: 'symbol'","exception_name":"KeyError"}
{"level":"ERROR","location":"[__subscribe_resp:707] data_ws","message":"'symbol'","timestamp":"2023-08-19 22:57:31,971+0530","service":"FyersDataSocket","exception":"Traceback (most recent call last):\n  File \"C:\\Users\\Sayan\\AppData\\Local\\Programs\\Python\\Python311\\Lib\\site-packages\\fyers_apiv3\\FyersWebsocket\\data_ws.py\", line 688, in __subscribe_resp\n    self.On_message(\n  File \"C:\\Users\\Sayan\\AppData\\Local\\Programs\\Python\\Python311\\Lib\\site-packages\\fyers_apiv3\\FyersWebsocket\\data_ws.py\", line 1403, in On_message\n    self.OnMessage(message)\n  File \"c:\\sayan's-project\\fyers\\fy_websocket.py\", line 9, in onmessage\n    print(message['symbol'])\n          ~~~~~~~^^^^^^^^^^\nKeyError: 'symbol'","exception_name":"KeyError"}
{"level":"ERROR","location":"[__response_output:976] data_ws","message":"cannot access local variable 'data_type' where it is not associated with a value","timestamp":"2023-08-19 22:57:33,465+0530","service":"FyersDataSocket","exception":"Traceback (most recent call last):\n  File \"C:\\Users\\Sayan\\AppData\\Local\\Programs\\Python\\Python311\\Lib\\site-packages\\fyers_apiv3\\FyersWebsocket\\data_ws.py\", line 973, in __response_output\n    self.On_message(response)\n  File \"C:\\Users\\Sayan\\AppData\\Local\\Programs\\Python\\Python311\\Lib\\site-packages\\fyers_apiv3\\FyersWebsocket\\data_ws.py\", line 1403, in On_message\n    self.OnMessage(message)\n  File \"c:\\sayan's-project\\fyers\\fy_websocket.py\", line 19, in onmessage\n    fyers.subscribe(symbols=symbols, data_type=data_type)\n                            ^^^^^^^\nUnboundLocalError: cannot access local variable 'data_type' where it is not associated with a value","exception_name":"UnboundLocalError"}
{"level":"ERROR","location":"[__unsubscribe_resp:761] data_ws","message":"'symbol'","timestamp":"2023-08-19 22:57:33,527+0530","service":"FyersDataSocket","exception":"Traceback (most recent call last):\n  File \"C:\\Users\\Sayan\\AppData\\Local\\Programs\\Python\\Python311\\Lib\\site-packages\\fyers_apiv3\\FyersWebsocket\\data_ws.py\", line 730, in __unsubscribe_resp\n    self.On_message(\n  File \"C:\\Users\\Sayan\\AppData\\Local\\Programs\\Python\\Python311\\Lib\\site-packages\\fyers_apiv3\\FyersWebsocket\\data_ws.py\", line 1403, in On_message\n    self.OnMessage(message)\n  File \"c:\\sayan's-project\\fyers\\fy_websocket.py\", line 9, in onmessage\n    print(message['symbol'])\n          ~~~~~~~^^^^^^^^^^\nKeyError: 'symbol'","exception_name":"KeyError"}
{"level":"ERROR","location":"[__subscribe_resp:707] data_ws","message":"'symbol'","timestamp":"2023-08-19 22:57:33,683+0530","service":"FyersDataSocket","exception":"Traceback (most recent call last):\n  File \"C:\\Users\\Sayan\\AppData\\Local\\Programs\\Python\\Python311\\Lib\\site-packages\\fyers_apiv3\\FyersWebsocket\\data_ws.py\", line 688, in __subscribe_resp\n    self.On_message(\n  File \"C:\\Users\\Sayan\\AppData\\Local\\Programs\\Python\\Python311\\Lib\\site-packages\\fyers_apiv3\\FyersWebsocket\\data_ws.py\", line 1403, in On_message\n    self.OnMessage(message)\n  File \"c:\\sayan's-project\\fyers\\fy_websocket.py\", line 9, in onmessage\n    print(message['symbol'])\n          ~~~~~~~^^^^^^^^^^\nKeyError: 'symbol'","exception_name":"KeyError"}
{"level":"ERROR","location":"[__response_output:976] data_ws","message":"cannot access local variable 'data_type' where it is not associated with a value","timestamp":"2023-08-19 22:57:35,659+0530","service":"FyersDataSocket","exception":"Traceback (most recent call last):\n  File \"C:\\Users\\Sayan\\AppData\\Local\\Programs\\Python\\Python311\\Lib\\site-packages\\fyers_apiv3\\FyersWebsocket\\data_ws.py\", line 973, in __response_output\n    self.On_message(response)\n  File \"C:\\Users\\Sayan\\AppData\\Local\\Programs\\Python\\Python311\\Lib\\site-packages\\fyers_apiv3\\FyersWebsocket\\data_ws.py\", line 1403, in On_message\n    self.OnMessage(message)\n  File \"c:\\sayan's-project\\fyers\\fy_websocket.py\", line 19, in onmessage\n    fyers.subscribe(symbols=symbols, data_type=data_type)\n                            ^^^^^^^\nUnboundLocalError: cannot access local variable 'data_type' where it is not associated with a value","exception_name":"UnboundLocalError"}
{"level":"ERROR","location":"[__unsubscribe_resp:761] data_ws","message":"'symbol'","timestamp":"2023-08-19 22:57:35,939+0530","service":"FyersDataSocket","exception":"Traceback (most recent call last):\n  File \"C:\\Users\\Sayan\\AppData\\Local\\Programs\\Python\\Python311\\Lib\\site-packages\\fyers_apiv3\\FyersWebsocket\\data_ws.py\", line 730, in __unsubscribe_resp\n    self.On_message(\n  File \"C:\\Users\\Sayan\\AppData\\Local\\Programs\\Python\\Python311\\Lib\\site-packages\\fyers_apiv3\\FyersWebsocket\\data_ws.py\", line 1403, in On_message\n    self.OnMessage(message)\n  File \"c:\\sayan's-project\\fyers\\fy_websocket.py\", line 9, in onmessage\n    print(message['symbol'])\n          ~~~~~~~^^^^^^^^^^\nKeyError: 'symbol'","exception_name":"KeyError"}
{"level":"ERROR","location":"[__subscribe_resp:707] data_ws","message":"'symbol'","timestamp":"2023-08-19 22:57:36,079+0530","service":"FyersDataSocket","exception":"Traceback (most recent call last):\n  File \"C:\\Users\\Sayan\\AppData\\Local\\Programs\\Python\\Python311\\Lib\\site-packages\\fyers_apiv3\\FyersWebsocket\\data_ws.py\", line 688, in __subscribe_resp\n    self.On_message(\n  File \"C:\\Users\\Sayan\\AppData\\Local\\Programs\\Python\\Python311\\Lib\\site-packages\\fyers_apiv3\\FyersWebsocket\\data_ws.py\", line 1403, in On_message\n    self.OnMessage(message)\n  File \"c:\\sayan's-project\\fyers\\fy_websocket.py\", line 9, in onmessage\n    print(message['symbol'])\n          ~~~~~~~^^^^^^^^^^\nKeyError: 'symbol'","exception_name":"KeyError"}
{"level":"ERROR","location":"[__response_output:976] data_ws","message":"cannot access local variable 'data_type' where it is not associated with a value","timestamp":"2023-08-19 22:57:39,949+0530","service":"FyersDataSocket","exception":"Traceback (most recent call last):\n  File \"C:\\Users\\Sayan\\AppData\\Local\\Programs\\Python\\Python311\\Lib\\site-packages\\fyers_apiv3\\FyersWebsocket\\data_ws.py\", line 973, in __response_output\n    self.On_message(response)\n  File \"C:\\Users\\Sayan\\AppData\\Local\\Programs\\Python\\Python311\\Lib\\site-packages\\fyers_apiv3\\FyersWebsocket\\data_ws.py\", line 1403, in On_message\n    self.OnMessage(message)\n  File \"c:\\sayan's-project\\fyers\\fy_websocket.py\", line 19, in onmessage\n    fyers.subscribe(symbols=symbols, data_type=data_type)\n                            ^^^^^^^\nUnboundLocalError: cannot access local variable 'data_type' where it is not associated with a value","exception_name":"UnboundLocalError"}
{"level":"ERROR","location":"[__unsubscribe_resp:761] data_ws","message":"'symbol'","timestamp":"2023-08-19 22:57:40,150+0530","service":"FyersDataSocket","exception":"Traceback (most recent call last):\n  File \"C:\\Users\\Sayan\\AppData\\Local\\Programs\\Python\\Python311\\Lib\\site-packages\\fyers_apiv3\\FyersWebsocket\\data_ws.py\", line 730, in __unsubscribe_resp\n    self.On_message(\n  File \"C:\\Users\\Sayan\\AppData\\Local\\Programs\\Python\\Python311\\Lib\\site-packages\\fyers_apiv3\\FyersWebsocket\\data_ws.py\", line 1403, in On_message\n    self.OnMessage(message)\n  File \"c:\\sayan's-project\\fyers\\fy_websocket.py\", line 9, in onmessage\n    print(message['symbol'])\n          ~~~~~~~^^^^^^^^^^\nKeyError: 'symbol'","exception_name":"KeyError"}
{"level":"ERROR","location":"[__subscribe_resp:707] data_ws","message":"'symbol'","timestamp":"2023-08-19 22:57:40,337+0530","service":"FyersDataSocket","exception":"Traceback (most recent call last):\n  File \"C:\\Users\\Sayan\\AppData\\Local\\Programs\\Python\\Python311\\Lib\\site-packages\\fyers_apiv3\\FyersWebsocket\\data_ws.py\", line 688, in __subscribe_resp\n    self.On_message(\n  File \"C:\\Users\\Sayan\\AppData\\Local\\Programs\\Python\\Python311\\Lib\\site-packages\\fyers_apiv3\\FyersWebsocket\\data_ws.py\", line 1403, in On_message\n    self.OnMessage(message)\n  File \"c:\\sayan's-project\\fyers\\fy_websocket.py\", line 9, in onmessage\n    print(message['symbol'])\n          ~~~~~~~^^^^^^^^^^\nKeyError: 'symbol'","exception_name":"KeyError"}
{"level":"ERROR","location":"[__auth_resp:666] data_ws","message":"'symbol'","timestamp":"2023-08-21 09:26:09,292+0530","service":"FyersDataSocket","exception":"Traceback (most recent call last):\n  File \"C:\\Users\\Sayan\\AppData\\Local\\Programs\\Python\\Python311\\Lib\\site-packages\\fyers_apiv3\\FyersWebsocket\\data_ws.py\", line 643, in __auth_resp\n    self.On_message(\n  File \"C:\\Users\\Sayan\\AppData\\Local\\Programs\\Python\\Python311\\Lib\\site-packages\\fyers_apiv3\\FyersWebsocket\\data_ws.py\", line 1403, in On_message\n    self.OnMessage(message)\n  File \"c:\\sayan's-project\\fyers\\fy_websocket.py\", line 9, in onmessage\n    print(message['symbol'])\n          ~~~~~~~^^^^^^^^^^\nKeyError: 'symbol'","exception_name":"KeyError"}
{"level":"ERROR","location":"[__lite_full_mode_resp:823] data_ws","message":"'symbol'","timestamp":"2023-08-21 09:26:09,828+0530","service":"FyersDataSocket","exception":"Traceback (most recent call last):\n  File \"C:\\Users\\Sayan\\AppData\\Local\\Programs\\Python\\Python311\\Lib\\site-packages\\fyers_apiv3\\FyersWebsocket\\data_ws.py\", line 805, in __lite_full_mode_resp\n    self.On_message(\n  File \"C:\\Users\\Sayan\\AppData\\Local\\Programs\\Python\\Python311\\Lib\\site-packages\\fyers_apiv3\\FyersWebsocket\\data_ws.py\", line 1403, in On_message\n    self.OnMessage(message)\n  File \"c:\\sayan's-project\\fyers\\fy_websocket.py\", line 9, in onmessage\n    print(message['symbol'])\n          ~~~~~~~^^^^^^^^^^\nKeyError: 'symbol'","exception_name":"KeyError"}
{"level":"ERROR","location":"[__subscribe_resp:707] data_ws","message":"'symbol'","timestamp":"2023-08-21 09:26:11,302+0530","service":"FyersDataSocket","exception":"Traceback (most recent call last):\n  File \"C:\\Users\\Sayan\\AppData\\Local\\Programs\\Python\\Python311\\Lib\\site-packages\\fyers_apiv3\\FyersWebsocket\\data_ws.py\", line 688, in __subscribe_resp\n    self.On_message(\n  File \"C:\\Users\\Sayan\\AppData\\Local\\Programs\\Python\\Python311\\Lib\\site-packages\\fyers_apiv3\\FyersWebsocket\\data_ws.py\", line 1403, in On_message\n    self.OnMessage(message)\n  File \"c:\\sayan's-project\\fyers\\fy_websocket.py\", line 9, in onmessage\n    print(message['symbol'])\n          ~~~~~~~^^^^^^^^^^\nKeyError: 'symbol'","exception_name":"KeyError"}
{"level":"ERROR","location":"[__auth_resp:666] data_ws","message":"'symbol'","timestamp":"2023-08-21 09:26:45,020+0530","service":"FyersDataSocket","exception":"Traceback (most recent call last):\n  File \"C:\\Users\\Sayan\\AppData\\Local\\Programs\\Python\\Python311\\Lib\\site-packages\\fyers_apiv3\\FyersWebsocket\\data_ws.py\", line 643, in __auth_resp\n    self.On_message(\n  File \"C:\\Users\\Sayan\\AppData\\Local\\Programs\\Python\\Python311\\Lib\\site-packages\\fyers_apiv3\\FyersWebsocket\\data_ws.py\", line 1403, in On_message\n    self.OnMessage(message)\n  File \"c:\\sayan's-project\\fyers\\fy_websocket.py\", line 9, in onmessage\n    print(message['symbol'])\n          ~~~~~~~^^^^^^^^^^\nKeyError: 'symbol'","exception_name":"KeyError"}
{"level":"ERROR","location":"[__lite_full_mode_resp:823] data_ws","message":"'symbol'","timestamp":"2023-08-21 09:26:45,464+0530","service":"FyersDataSocket","exception":"Traceback (most recent call last):\n  File \"C:\\Users\\Sayan\\AppData\\Local\\Programs\\Python\\Python311\\Lib\\site-packages\\fyers_apiv3\\FyersWebsocket\\data_ws.py\", line 805, in __lite_full_mode_resp\n    self.On_message(\n  File \"C:\\Users\\Sayan\\AppData\\Local\\Programs\\Python\\Python311\\Lib\\site-packages\\fyers_apiv3\\FyersWebsocket\\data_ws.py\", line 1403, in On_message\n    self.OnMessage(message)\n  File \"c:\\sayan's-project\\fyers\\fy_websocket.py\", line 9, in onmessage\n    print(message['symbol'])\n          ~~~~~~~^^^^^^^^^^\nKeyError: 'symbol'","exception_name":"KeyError"}
{"level":"ERROR","location":"[__subscribe_resp:707] data_ws","message":"'symbol'","timestamp":"2023-08-21 09:26:47,088+0530","service":"FyersDataSocket","exception":"Traceback (most recent call last):\n  File \"C:\\Users\\Sayan\\AppData\\Local\\Programs\\Python\\Python311\\Lib\\site-packages\\fyers_apiv3\\FyersWebsocket\\data_ws.py\", line 688, in __subscribe_resp\n    self.On_message(\n  File \"C:\\Users\\Sayan\\AppData\\Local\\Programs\\Python\\Python311\\Lib\\site-packages\\fyers_apiv3\\FyersWebsocket\\data_ws.py\", line 1403, in On_message\n    self.OnMessage(message)\n  File \"c:\\sayan's-project\\fyers\\fy_websocket.py\", line 9, in onmessage\n    print(message['symbol'])\n          ~~~~~~~^^^^^^^^^^\nKeyError: 'symbol'","exception_name":"KeyError"}
{"level":"ERROR","location":"[__auth_resp:666] data_ws","message":"'ltp'","timestamp":"2023-08-21 09:27:04,609+0530","service":"FyersDataSocket","exception":"Traceback (most recent call last):\n  File \"C:\\Users\\Sayan\\AppData\\Local\\Programs\\Python\\Python311\\Lib\\site-packages\\fyers_apiv3\\FyersWebsocket\\data_ws.py\", line 643, in __auth_resp\n    self.On_message(\n  File \"C:\\Users\\Sayan\\AppData\\Local\\Programs\\Python\\Python311\\Lib\\site-packages\\fyers_apiv3\\FyersWebsocket\\data_ws.py\", line 1403, in On_message\n    self.OnMessage(message)\n  File \"c:\\sayan's-project\\fyers\\fy_websocket.py\", line 10, in onmessage\n    print(message['ltp'])\n          ~~~~~~~^^^^^^^\nKeyError: 'ltp'","exception_name":"KeyError"}
{"level":"ERROR","location":"[__lite_full_mode_resp:823] data_ws","message":"'ltp'","timestamp":"2023-08-21 09:27:05,051+0530","service":"FyersDataSocket","exception":"Traceback (most recent call last):\n  File \"C:\\Users\\Sayan\\AppData\\Local\\Programs\\Python\\Python311\\Lib\\site-packages\\fyers_apiv3\\FyersWebsocket\\data_ws.py\", line 805, in __lite_full_mode_resp\n    self.On_message(\n  File \"C:\\Users\\Sayan\\AppData\\Local\\Programs\\Python\\Python311\\Lib\\site-packages\\fyers_apiv3\\FyersWebsocket\\data_ws.py\", line 1403, in On_message\n    self.OnMessage(message)\n  File \"c:\\sayan's-project\\fyers\\fy_websocket.py\", line 10, in onmessage\n    print(message['ltp'])\n          ~~~~~~~^^^^^^^\nKeyError: 'ltp'","exception_name":"KeyError"}
{"level":"ERROR","location":"[__subscribe_resp:707] data_ws","message":"'ltp'","timestamp":"2023-08-21 09:27:05,763+0530","service":"FyersDataSocket","exception":"Traceback (most recent call last):\n  File \"C:\\Users\\Sayan\\AppData\\Local\\Programs\\Python\\Python311\\Lib\\site-packages\\fyers_apiv3\\FyersWebsocket\\data_ws.py\", line 688, in __subscribe_resp\n    self.On_message(\n  File \"C:\\Users\\Sayan\\AppData\\Local\\Programs\\Python\\Python311\\Lib\\site-packages\\fyers_apiv3\\FyersWebsocket\\data_ws.py\", line 1403, in On_message\n    self.OnMessage(message)\n  File \"c:\\sayan's-project\\fyers\\fy_websocket.py\", line 10, in onmessage\n    print(message['ltp'])\n          ~~~~~~~^^^^^^^\nKeyError: 'ltp'","exception_name":"KeyError"}
{"level":"ERROR","location":"[__auth_resp:666] data_ws","message":"'symbol'","timestamp":"2023-08-21 09:41:01,873+0530","service":"FyersDataSocket","exception":"Traceback (most recent call last):\n  File \"C:\\Users\\Sayan\\AppData\\Local\\Programs\\Python\\Python311\\Lib\\site-packages\\fyers_apiv3\\FyersWebsocket\\data_ws.py\", line 643, in __auth_resp\n    self.On_message(\n  File \"C:\\Users\\Sayan\\AppData\\Local\\Programs\\Python\\Python311\\Lib\\site-packages\\fyers_apiv3\\FyersWebsocket\\data_ws.py\", line 1403, in On_message\n    self.OnMessage(message)\n  File \"c:\\sayan's-project\\fyers\\fy_websocket.py\", line 10, in onmessage\n    if message['symbol'] == \"NSE:NIFTY50-INDEX\" and message['ltp'] > 19350:\n       ~~~~~~~^^^^^^^^^^\nKeyError: 'symbol'","exception_name":"KeyError"}
{"level":"ERROR","location":"[__lite_full_mode_resp:823] data_ws","message":"'symbol'","timestamp":"2023-08-21 09:41:02,555+0530","service":"FyersDataSocket","exception":"Traceback (most recent call last):\n  File \"C:\\Users\\Sayan\\AppData\\Local\\Programs\\Python\\Python311\\Lib\\site-packages\\fyers_apiv3\\FyersWebsocket\\data_ws.py\", line 805, in __lite_full_mode_resp\n    self.On_message(\n  File \"C:\\Users\\Sayan\\AppData\\Local\\Programs\\Python\\Python311\\Lib\\site-packages\\fyers_apiv3\\FyersWebsocket\\data_ws.py\", line 1403, in On_message\n    self.OnMessage(message)\n  File \"c:\\sayan's-project\\fyers\\fy_websocket.py\", line 10, in onmessage\n    if message['symbol'] == \"NSE:NIFTY50-INDEX\" and message['ltp'] > 19350:\n       ~~~~~~~^^^^^^^^^^\nKeyError: 'symbol'","exception_name":"KeyError"}
{"level":"ERROR","location":"[__subscribe_resp:707] data_ws","message":"'symbol'","timestamp":"2023-08-21 09:41:04,642+0530","service":"FyersDataSocket","exception":"Traceback (most recent call last):\n  File \"C:\\Users\\Sayan\\AppData\\Local\\Programs\\Python\\Python311\\Lib\\site-packages\\fyers_apiv3\\FyersWebsocket\\data_ws.py\", line 688, in __subscribe_resp\n    self.On_message(\n  File \"C:\\Users\\Sayan\\AppData\\Local\\Programs\\Python\\Python311\\Lib\\site-packages\\fyers_apiv3\\FyersWebsocket\\data_ws.py\", line 1403, in On_message\n    self.OnMessage(message)\n  File \"c:\\sayan's-project\\fyers\\fy_websocket.py\", line 10, in onmessage\n    if message['symbol'] == \"NSE:NIFTY50-INDEX\" and message['ltp'] > 19350:\n       ~~~~~~~^^^^^^^^^^\nKeyError: 'symbol'","exception_name":"KeyError"}
{"level":"ERROR","location":"[__auth_resp:666] data_ws","message":"'symbol'","timestamp":"2023-08-21 09:45:10,166+0530","service":"FyersDataSocket","exception":"Traceback (most recent call last):\n  File \"C:\\Users\\Sayan\\AppData\\Local\\Programs\\Python\\Python311\\Lib\\site-packages\\fyers_apiv3\\FyersWebsocket\\data_ws.py\", line 643, in __auth_resp\n    self.On_message(\n  File \"C:\\Users\\Sayan\\AppData\\Local\\Programs\\Python\\Python311\\Lib\\site-packages\\fyers_apiv3\\FyersWebsocket\\data_ws.py\", line 1403, in On_message\n    self.OnMessage(message)\n  File \"c:\\sayan's-project\\fyers\\fy_websocket.py\", line 10, in onmessage\n    if message['symbol'] == \"NSE:NIFTY50-INDEX\" and message['ltp'] > 19350:\n       ~~~~~~~^^^^^^^^^^\nKeyError: 'symbol'","exception_name":"KeyError"}
{"level":"ERROR","location":"[__lite_full_mode_resp:823] data_ws","message":"'symbol'","timestamp":"2023-08-21 09:45:10,576+0530","service":"FyersDataSocket","exception":"Traceback (most recent call last):\n  File \"C:\\Users\\Sayan\\AppData\\Local\\Programs\\Python\\Python311\\Lib\\site-packages\\fyers_apiv3\\FyersWebsocket\\data_ws.py\", line 805, in __lite_full_mode_resp\n    self.On_message(\n  File \"C:\\Users\\Sayan\\AppData\\Local\\Programs\\Python\\Python311\\Lib\\site-packages\\fyers_apiv3\\FyersWebsocket\\data_ws.py\", line 1403, in On_message\n    self.OnMessage(message)\n  File \"c:\\sayan's-project\\fyers\\fy_websocket.py\", line 10, in onmessage\n    if message['symbol'] == \"NSE:NIFTY50-INDEX\" and message['ltp'] > 19350:\n       ~~~~~~~^^^^^^^^^^\nKeyError: 'symbol'","exception_name":"KeyError"}
{"level":"ERROR","location":"[__subscribe_resp:707] data_ws","message":"'symbol'","timestamp":"2023-08-21 09:45:12,043+0530","service":"FyersDataSocket","exception":"Traceback (most recent call last):\n  File \"C:\\Users\\Sayan\\AppData\\Local\\Programs\\Python\\Python311\\Lib\\site-packages\\fyers_apiv3\\FyersWebsocket\\data_ws.py\", line 688, in __subscribe_resp\n    self.On_message(\n  File \"C:\\Users\\Sayan\\AppData\\Local\\Programs\\Python\\Python311\\Lib\\site-packages\\fyers_apiv3\\FyersWebsocket\\data_ws.py\", line 1403, in On_message\n    self.OnMessage(message)\n  File \"c:\\sayan's-project\\fyers\\fy_websocket.py\", line 10, in onmessage\n    if message['symbol'] == \"NSE:NIFTY50-INDEX\" and message['ltp'] > 19350:\n       ~~~~~~~^^^^^^^^^^\nKeyError: 'symbol'","exception_name":"KeyError"}
